Workbook

Sheet Planner
A1: FeasaBULL Diet Planner — person in, cheapest balanced day out
A2: Step 1: enter the person (same inputs as FeasaBULL Calories). Step 2: targets are calculated with the site's equations. Step 3: pick a diet and re-solve (box at right). Blue = inputs.
B4: 1. PERSON (same inputs as the FeasaBULL Calories site) | F4: 4. RESULT | L4: HOW TO RE-SOLVE FOR A NEW PERSON OR DIET
B5: Sex | C5: Male | F5: Cost per day | G5: ='Matrix Model'!C184 -> 3.018031 | L5: 1. Change the blue inputs on this sheet (and Food Data if needed).
B6: Age (years) | C6: 21 | F6: Cost per week | G6: =G5*7 -> 21.126217 | L6: 2. Data → Solver (Excel: File → Options → Add-ins → enable Solver Add-in).
B7: Height (ft, in) | C7: 5 | D7: 8 | F7: Rules violated | G7: ='Matrix Model'!C185 -> 0 | L7: 3. Set Objective: 'Matrix Model'!$C$184 To: Min
B8: Weight (lb) | C8: 155 | F8: Status | G8: =IF(G7=0,"✓ Plan meets every rule","✗ Re-run Solver: the plan does not fit these inputs") -> ✓ Plan meets every rule | L8: 4. By Changing Variable Cells: 'Matrix Model'!$C$112:$C$182
B9: Activity level | C9: Active | L9: 5. Subject to the Constraints (Add each):
B10: Goal | C10: Maintain | F10: Daily totals vs targets | L10: 'Matrix Model'!$D$40:$D$58 >= 'Matrix Model'!$C$40:$C$58
B11: Activity coefficients | C11: IOM 2005 (corrected) | D11: or "Same as current site" to reproduce the live site exactly | F11: Nutrient | G11: Plan | H11: Min | I11: Max | L11: 'Matrix Model'!$D$59:$D$107 <= 'Matrix Model'!$C$59:$C$107
B12: Example: the site's own placeholder person (male, 21, 5'8", 155 lb, active, maintain). | F12: Calories (kcal) | G12: ='Matrix Model'!C189 -> 2878.5 | H12: =Planner!$E$16*(1-Planner!$C$42) -> 2878.5 | I12: =Planner!$E$16*(1+Planner!$C$42) -> 3181.5 | L12: 'Matrix Model'!$C$112:$C$182 <= 'Matrix Model'!$D$112:$D$182
F13: Protein (g) | G13: ='Matrix Model'!C190 -> 112 | H13: =MAX(N(Planner!$E$17),'Matrix Model'!$C$8*$G$12/4) -> 112 | I13: ='Matrix Model'!$D$8*$G$12/4 -> 251.86875 | L13: 'Matrix Model'!$C$112:$C$182 >= 'Matrix Model'!$E$112:$E$182
B14: 2. DAILY TARGETS (calculated with the site's equations — type in Override to change one) | F14: Carbohydrate (g) | G14: ='Matrix Model'!C191 -> 467.75625 | H14: ='Matrix Model'!$C$9*$G$12/4 -> 323.83125 | I14: ='Matrix Model'!$D$9*$G$12/4 -> 467.75625 | L14: 6. Tick "Make Unconstrained Variables Non-Negative", choose "Simplex LP", click Solve.
B15: Target | C15: Calculated | D15: Override | E15: Used by the model | F15: Fat (g) | G15: ='Matrix Model'!C192 -> 66.160131 | H15: ='Matrix Model'!$C$10*$G$12/9 -> 63.966667 | I15: ='Matrix Model'!$D$10*$G$12/9 -> 111.94167 | L15: (68 constraint cells — inside Excel Solver's 100-cell limit; bounds on x do not count.)
B16: Calories (kcal/day) | C16: =MAX(IF(Planner!$C$5="Male",'DRI Tables'!$E$17,'DRI Tables'!$E$18),ROUND(($C$31+$C$32)/10,0)*10) -> 3030 | E16: =IF(AND(D16="",C16=""),"",IF(D16="",C16,D16)) -> 3030 | F16: Fiber (g) | G16: ='Matrix Model'!C193 -> 47.918555 | H16: =Planner!$E$18 -> 42 | L16: 7. Status above turns ✓. The website runs the same model instantly (src/lib/dietOptimizer.js).
B17: Protein at least (g) — 1.6 g/kg, kept in 10–30% of kcal | C17: =MIN(MAX(ROUND(1.6*$C$28,0),ROUND(0.1*$C$16/4,0)),ROUND(0.3*$C$16/4,0)) -> 112 | E17: =IF(AND(D17="",C17=""),"",IF(D17="",C17,D17)) -> 112 | F17: Total sugars (g) | G17: ='Matrix Model'!C194 -> 66.951843 | I17: =IF(Planner!$E$24="","",Planner!$E$24)
B18: Fiber at least (g) — 14 g per 1,000 kcal | C18: =ROUND(14*$C$16/1000,0) -> 42 | E18: =IF(AND(D18="",C18=""),"",IF(D18="",C18,D18)) -> 42 | F18: Calcium (mg) | G18: ='Matrix Model'!C195 -> 1000 | H18: =Planner!$E$19 -> 1000
B19: Calcium at least (mg) | C19: =IF(Planner!$C$5="Male",INDEX('DRI Tables'!$E$23:$E$27,MATCH($C$29,'DRI Tables'!$A$23:$A$27,0)),INDEX('DRI Tables'!$F$23:$F$27,MATCH($C$29,'DRI Tables'!$A$23:$A$27,0))) -> 1000 | E19: =IF(AND(D19="",C19=""),"",IF(D19="",C19,D19)) -> 1000 | F19: Iron (mg) | G19: ='Matrix Model'!C196 -> 23.307801 | H19: =Planner!$E$20 -> 8
B20: Iron at least (mg) | C20: =IF(Planner!$C$5="Male",INDEX('DRI Tables'!$G$23:$G$27,MATCH($C$29,'DRI Tables'!$A$23:$A$27,0)),INDEX('DRI Tables'!$H$23:$H$27,MATCH($C$29,'DRI Tables'!$A$23:$A$27,0))) -> 8 | E20: =IF(AND(D20="",C20=""),"",IF(D20="",C20,D20)) -> 8 | F20: Potassium (mg) | G20: ='Matrix Model'!C197 -> 5247.6431 | H20: =Planner!$E$21 -> 3400
B21: Potassium at least (mg) | C21: =IF(Planner!$C$5="Male",INDEX('DRI Tables'!$I$23:$I$27,MATCH($C$29,'DRI Tables'!$A$23:$A$27,0)),INDEX('DRI Tables'!$J$23:$J$27,MATCH($C$29,'DRI Tables'!$A$23:$A$27,0))) -> 3400 | E21: =IF(AND(D21="",C21=""),"",IF(D21="",C21,D21)) -> 3400 | F21: Sodium (mg) | G21: ='Matrix Model'!C198 -> 768.58413 | I21: =Planner!$E$23 -> 2300
B22: Vitamin C at least (mg) | C22: =IF(Planner!$C$5="Male",INDEX('DRI Tables'!$C$23:$C$27,MATCH($C$29,'DRI Tables'!$A$23:$A$27,0)),INDEX('DRI Tables'!$D$23:$D$27,MATCH($C$29,'DRI Tables'!$A$23:$A$27,0))) -> 90 | E22: =IF(AND(D22="",C22=""),"",IF(D22="",C22,D22)) -> 90 | F22: Vitamin C (mg) | G22: ='Matrix Model'!C199 -> 166.14307 | H22: =Planner!$E$22 -> 90
B23: Sodium under (mg) | C23: 2300 | E23: =IF(AND(D23="",C23=""),"",IF(D23="",C23,D23)) -> 2300
B24: Total sugars under (g, optional) | E24: =IF(AND(D24="",C24=""),"",IF(D24="",C24,D24))
F25: Your day, by meal (lunch and dinner share a batch-cooked base — cook once, eat twice)
B26: How the targets were calculated | F26: Breakfast | G26: grams | H26: servings | I26: kcal | J26: protein (g)
B27: Height (cm) | C27: =ROUND((Planner!$C$7*12+N(Planner!$D$7))*2.54,0) -> 173 | F27: =IFERROR(INDEX('Matrix Model'!$B$112:$B$182,MATCH(1,'Matrix Model'!$N$112:$N$182,0)),"") -> Eggs (large) | G27: =IFERROR(INDEX('Matrix Model'!$J$112:$J$182,MATCH(1,'Matrix Model'!$N$112:$N$182,0)),"") -> 126.37551 | H27: =IFERROR(G27/INDEX('Food Data'!$N$6:$N$76,MATCH(1,'Matrix Model'!$N$112:$N$182,0)),"") -> 2.5275102 | I27: =IFERROR(G27*INDEX('Food Data'!$AH$6:$AH$76,MATCH(1,'Matrix Model'!$N$112:$N$182,0))/100,"") -> 180.71698 | J27: =IFERROR(G27*INDEX('Food Data'!$AI$6:$AI$76,MATCH(1,'Matrix Model'!$N$112:$N$182,0))/100,"") -> 15.872764
B28: Weight (kg) | C28: =ROUND(Planner!$C$8*0.45359237,1) -> 70.3 | F28: =IFERROR(INDEX('Matrix Model'!$B$112:$B$182,MATCH(2,'Matrix Model'!$N$112:$N$182,0)),"") -> Peanut butter | G28: =IFERROR(INDEX('Matrix Model'!$J$112:$J$182,MATCH(2,'Matrix Model'!$N$112:$N$182,0)),"") -> 32 | H28: =IFERROR(G28/INDEX('Food Data'!$N$6:$N$76,MATCH(2,'Matrix Model'!$N$112:$N$182,0)),"") -> 1 | I28: =IFERROR(G28*INDEX('Food Data'!$AH$6:$AH$76,MATCH(2,'Matrix Model'!$N$112:$N$182,0))/100,"") -> 191.36 | J28: =IFERROR(G28*INDEX('Food Data'!$AI$6:$AI$76,MATCH(2,'Matrix Model'!$N$112:$N$182,0))/100,"") -> 7.1072
B29: Age bracket | C29: =IF(Planner!$C$6<19,"teen",IF(Planner!$C$6<=30,"young",IF(Planner!$C$6<=50,"mid",IF(Planner!$C$6<=70,"older","oldest")))) -> young | F29: =IFERROR(INDEX('Matrix Model'!$B$112:$B$182,MATCH(3,'Matrix Model'!$N$112:$N$182,0)),"") -> 2% milk | G29: =IFERROR(INDEX('Matrix Model'!$J$112:$J$182,MATCH(3,'Matrix Model'!$N$112:$N$182,0)),"") -> 235.12344 | H29: =IFERROR(G29/INDEX('Food Data'!$N$6:$N$76,MATCH(3,'Matrix Model'!$N$112:$N$182,0)),"") -> 0.96362066 | I29: =IFERROR(G29*INDEX('Food Data'!$AH$6:$AH$76,MATCH(3,'Matrix Model'!$N$112:$N$182,0))/100,"") -> 117.56172 | J29: =IFERROR(G29*INDEX('Food Data'!$AI$6:$AI$76,MATCH(3,'Matrix Model'!$N$112:$N$182,0))/100,"") -> 7.7590736
B30: Activity coefficient (PA) | C30: =IF(Planner!$C$11="Same as current site",INDEX('DRI Tables'!$B$11:$E$14,IF(Planner!$C$6<19,IF(Planner!$C$5="Male",3,4),IF(Planner!$C$5="Male",1,2)),MATCH(Planner!$C$9,'DRI Tables'!$B$4:$E$4,0)),INDEX('DRI Tables'!$B$5:$E$8,IF(Planner!$C$6<19,IF(Planner!$C$5="Male",3,4),IF(Planner!$C$5="Male",1,2)),MATCH(Planner!$C$9,'DRI Tables'!$B$4:$E$4,0))) -> 1.25 | F30: =IFERROR(INDEX('Matrix Model'!$B$112:$B$182,MATCH(4,'Matrix Model'!$N$112:$N$182,0)),"") -> Rolled oats (dry) | G30: =IFERROR(INDEX('Matrix Model'!$J$112:$J$182,MATCH(4,'Matrix Model'!$N$112:$N$182,0)),"") -> 2.9924272 | H30: =IFERROR(G30/INDEX('Food Data'!$N$6:$N$76,MATCH(4,'Matrix Model'!$N$112:$N$182,0)),"") -> 0.07481068 | I30: =IFERROR(G30*INDEX('Food Data'!$AH$6:$AH$76,MATCH(4,'Matrix Model'!$N$112:$N$182,0))/100,"") -> 11.341299 | J30: =IFERROR(G30*INDEX('Food Data'!$AI$6:$AI$76,MATCH(4,'Matrix Model'!$N$112:$N$182,0))/100,"") -> 0.39350418
B31: Maintenance calories (IOM EER, rounded to 10) | C31: =ROUND(IF(Planner!$C$6<19,IF(Planner!$C$5="Male",88.5-61.9*Planner!$C$6+$C$30*(26.7*$C$28+903*($C$27/100))+25,135.3-30.8*Planner!$C$6+$C$30*(10*$C$28+934*($C$27/100))+IF(Planner!$C$11="Same as current site",20,25)),IF(Planner!$C$5="Male",662-9.53*Planner!$C$6+$C$30*(15.91*$C$28+539.6*($C$27/100)),354-6.91*Planner!$C$6+$C$30*(9.36*$C$28+726*($C$27/100))))/10,0)*10 -> 3030 | F31: =IFERROR(INDEX('Matrix Model'!$B$112:$B$182,MATCH(5,'Matrix Model'!$N$112:$N$182,0)),"") -> Bananas | G31: =IFERROR(INDEX('Matrix Model'!$J$112:$J$182,MATCH(5,'Matrix Model'!$N$112:$N$182,0)),"") -> 118 | H31: =IFERROR(G31/INDEX('Food Data'!$N$6:$N$76,MATCH(5,'Matrix Model'!$N$112:$N$182,0)),"") -> 1 | I31: =IFERROR(G31*INDEX('Food Data'!$AH$6:$AH$76,MATCH(5,'Matrix Model'!$N$112:$N$182,0))/100,"") -> 105.02 | J31: =IFERROR(G31*INDEX('Food Data'!$AI$6:$AI$76,MATCH(5,'Matrix Model'!$N$112:$N$182,0))/100,"") -> 1.2862
B32: Goal adjustment (kcal) | C32: =INDEX('DRI Tables'!$B$17:$B$19,MATCH(Planner!$C$10,'DRI Tables'!$A$17:$A$19,0)) -> 0 | F32: =IFERROR(INDEX('Matrix Model'!$B$112:$B$182,MATCH(6,'Matrix Model'!$N$112:$N$182,0)),"") | G32: =IFERROR(INDEX('Matrix Model'!$J$112:$J$182,MATCH(6,'Matrix Model'!$N$112:$N$182,0)),"") | H32: =IFERROR(G32/INDEX('Food Data'!$N$6:$N$76,MATCH(6,'Matrix Model'!$N$112:$N$182,0)),"") | I32: =IFERROR(G32*INDEX('Food Data'!$AH$6:$AH$76,MATCH(6,'Matrix Model'!$N$112:$N$182,0))/100,"") | J32: =IFERROR(G32*INDEX('Food Data'!$AI$6:$AI$76,MATCH(6,'Matrix Model'!$N$112:$N$182,0))/100,"")
B33: BMI | C33: =ROUND($C$28/(($C$27/100))^2,1) -> 23.5 | F33: =IFERROR(INDEX('Matrix Model'!$B$112:$B$182,MATCH(7,'Matrix Model'!$N$112:$N$182,0)),"") | G33: =IFERROR(INDEX('Matrix Model'!$J$112:$J$182,MATCH(7,'Matrix Model'!$N$112:$N$182,0)),"") | H33: =IFERROR(G33/INDEX('Food Data'!$N$6:$N$76,MATCH(7,'Matrix Model'!$N$112:$N$182,0)),"") | I33: =IFERROR(G33*INDEX('Food Data'!$AH$6:$AH$76,MATCH(7,'Matrix Model'!$N$112:$N$182,0))/100,"") | J33: =IFERROR(G33*INDEX('Food Data'!$AI$6:$AI$76,MATCH(7,'Matrix Model'!$N$112:$N$182,0))/100,"")
F34: =IFERROR(INDEX('Matrix Model'!$B$112:$B$182,MATCH(8,'Matrix Model'!$N$112:$N$182,0)),"") | G34: =IFERROR(INDEX('Matrix Model'!$J$112:$J$182,MATCH(8,'Matrix Model'!$N$112:$N$182,0)),"") | H34: =IFERROR(G34/INDEX('Food Data'!$N$6:$N$76,MATCH(8,'Matrix Model'!$N$112:$N$182,0)),"") | I34: =IFERROR(G34*INDEX('Food Data'!$AH$6:$AH$76,MATCH(8,'Matrix Model'!$N$112:$N$182,0))/100,"") | J34: =IFERROR(G34*INDEX('Food Data'!$AI$6:$AI$76,MATCH(8,'Matrix Model'!$N$112:$N$182,0))/100,"")
B35: 3. DIET & PRICES | F35: =IFERROR(INDEX('Matrix Model'!$B$112:$B$182,MATCH(9,'Matrix Model'!$N$112:$N$182,0)),"") | G35: =IFERROR(INDEX('Matrix Model'!$J$112:$J$182,MATCH(9,'Matrix Model'!$N$112:$N$182,0)),"") | H35: =IFERROR(G35/INDEX('Food Data'!$N$6:$N$76,MATCH(9,'Matrix Model'!$N$112:$N$182,0)),"") | I35: =IFERROR(G35*INDEX('Food Data'!$AH$6:$AH$76,MATCH(9,'Matrix Model'!$N$112:$N$182,0))/100,"") | J35: =IFERROR(G35*INDEX('Food Data'!$AI$6:$AI$76,MATCH(9,'Matrix Model'!$N$112:$N$182,0))/100,"")
B36: Diet | C36: Balanced | F36: Breakfast total | I36: ='Matrix Model'!D189 -> 606 | J36: ='Matrix Model'!D190 -> 32.418742
B37: What it means | C37: =INDEX(Diets!$B$5:$B$12,MATCH(Planner!$C$36,Diets!$A$5:$A$12,0)) -> USDA Acceptable Macronutrient Distribution Ranges; all foods allowed
B38: Macro split (% of calories) | C38: ="Protein "&TEXT('Matrix Model'!$C$8,"0%")&"–"&TEXT('Matrix Model'!$D$8,"0%")&", Carbs "&TEXT('Matrix Model'!$C$9,"0%")&"–"&TEXT('Matrix Model'!$D$9,"0%")&", Fat "&TEXT('Matrix Model'!$C$10,"0%")&"–"&TEXT('Matrix Model'!$D$10,"0%") -> Protein 10%–35%, Carbs 45%–65%, Fat 20%–35% | F38: Lunch | G38: grams | H38: servings | I38: kcal | J38: protein (g)
B39: Price source | C39: Walmart (Oct 2026) | D39: or "BLS U.S. average (Sep 2026)" — sensitivity check | F39: =IFERROR(INDEX('Matrix Model'!$B$112:$B$182,MATCH(1,'Matrix Model'!$O$112:$O$182,0)),"") -> Pinto beans (dry) | G39: =IFERROR(INDEX('Matrix Model'!$K$112:$K$182,MATCH(1,'Matrix Model'!$O$112:$O$182,0)),"") -> 72 | H39: =IFERROR(G39/INDEX('Food Data'!$N$6:$N$76,MATCH(1,'Matrix Model'!$O$112:$O$182,0)),"") -> 1.5 | I39: =IFERROR(G39*INDEX('Food Data'!$AH$6:$AH$76,MATCH(1,'Matrix Model'!$O$112:$O$182,0))/100,"") -> 249.84 | J39: =IFERROR(G39*INDEX('Food Data'!$AI$6:$AI$76,MATCH(1,'Matrix Model'!$O$112:$O$182,0))/100,"") -> 15.4224
F40: =IFERROR(INDEX('Matrix Model'!$B$112:$B$182,MATCH(2,'Matrix Model'!$O$112:$O$182,0)),"") -> Brown rice (dry) | G40: =IFERROR(INDEX('Matrix Model'!$K$112:$K$182,MATCH(2,'Matrix Model'!$O$112:$O$182,0)),"") -> 78.14669 | H40: =IFERROR(G40/INDEX('Food Data'!$N$6:$N$76,MATCH(2,'Matrix Model'!$O$112:$O$182,0)),"") -> 1.6988411 | I40: =IFERROR(G40*INDEX('Food Data'!$AH$6:$AH$76,MATCH(2,'Matrix Model'!$O$112:$O$182,0))/100,"") -> 286.79835 | J40: =IFERROR(G40*INDEX('Food Data'!$AI$6:$AI$76,MATCH(2,'Matrix Model'!$O$112:$O$182,0))/100,"") -> 5.8922604
B41: 4. BALANCE RULES (keep amounts realistic) | F41: =IFERROR(INDEX('Matrix Model'!$B$112:$B$182,MATCH(3,'Matrix Model'!$O$112:$O$182,0)),"") -> White rice (dry) | G41: =IFERROR(INDEX('Matrix Model'!$K$112:$K$182,MATCH(3,'Matrix Model'!$O$112:$O$182,0)),"") -> 92 | H41: =IFERROR(G41/INDEX('Food Data'!$N$6:$N$76,MATCH(3,'Matrix Model'!$O$112:$O$182,0)),"") -> 2 | I41: =IFERROR(G41*INDEX('Food Data'!$AH$6:$AH$76,MATCH(3,'Matrix Model'!$O$112:$O$182,0))/100,"") -> 335.8 | J41: =IFERROR(G41*INDEX('Food Data'!$AI$6:$AI$76,MATCH(3,'Matrix Model'!$O$112:$O$182,0))/100,"") -> 6.5596
...

Sheet DRI Tables
A1: DRI Tables — the numbers behind the person calculator
A2: Same values as the FeasaBULL Calories site. Activity coefficients: IOM (2005) EER equations, healthy-weight version.
A4: Group | B4: Inactive | C4: Low active | D4: Active | E4: Very active
A5: Men 19+ | B5: 1 | C5: 1.11 | D5: 1.25 | E5: 1.48
A6: Women 19+ | B6: 1 | C6: 1.12 | D6: 1.27 | E6: 1.45
A7: Boys 14–18 | B7: 1 | C7: 1.13 | D7: 1.26 | E7: 1.42
A8: Girls 14–18 | B8: 1 | C8: 1.16 | D8: 1.31 | E8: 1.56
A9: IOM 2005 values (used by default). Below: what the live FeasaBULL site uses today (men's values for everyone).
A10: Group (site) | B10: Inactive | C10: Low active | D10: Active | E10: Very active
A11: Men 19+ | B11: 1 | C11: 1.11 | D11: 1.25 | E11: 1.48
A12: Women 19+ | B12: 1 | C12: 1.11 | D12: 1.25 | E12: 1.48
A13: Boys 14–18 | B13: 1 | C13: 1.13 | D13: 1.26 | E13: 1.42
A14: Girls 14–18 | B14: 1 | C14: 1.13 | D14: 1.26 | E14: 1.42
A16: Goal | B16: kcal change | D16: Calorie floor
A17: Lose fat | B17: -500 | D17: Male | E17: 1500
A18: Maintain | B18: 0 | D18: Female | E18: 1200
A19: Build muscle | B19: 350
A22: Age bracket | B22: Ages | C22: Vit C (M) | D22: Vit C (F) | E22: Calcium (M) | F22: Calcium (F) | G22: Iron (M) | H22: Iron (F) | I22: Potassium (M) | J22: Potassium (F)
A23: teen | B23: 14–18 | C23: 75 | D23: 65 | E23: 1300 | F23: 1300 | G23: 11 | H23: 15 | I23: 3000 | J23: 2300
A24: young | B24: 19–30 | C24: 90 | D24: 75 | E24: 1000 | F24: 1000 | G24: 8 | H24: 18 | I24: 3400 | J24: 2600
A25: mid | B25: 31–50 | C25: 90 | D25: 75 | E25: 1000 | F25: 1000 | G25: 8 | H25: 18 | I25: 3400 | J25: 2600
A26: older | B26: 51–70 | C26: 90 | D26: 75 | E26: 1000 | F26: 1200 | G26: 8 | H26: 8 | I26: 3400 | J26: 2600
A27: oldest | B27: 71+ | C27: 90 | D27: 75 | E27: 1200 | F27: 1200 | G27: 8 | H27: 8 | I27: 3400 | J27: 2600
A29: Units: vitamin C, calcium, potassium in mg; iron in mg. Fiber = 14 g per 1,000 kcal. Sodium: keep under 2,300 mg.

Sheet Food Data
A1: Food Data — 71 common foods, sorted by group and type
A2: Prices: Walmart (Oct 2026, regular price) with BLS U.S. average (Sep 2026) for reference. Nutrients: USDA SR28, per 100 g edible.
A3: Blue = data you can edit (prices, servings, caps, exclusions). Black = formulas. Yellow = check this price. Edible yield removes bone, peel, shells (USDA refuse %).
A5: # | B5: Group | C5: Type | D5: Food | E5: Store product (Walmart) | F5: Price ($) | G5: Package as bought (g) | H5: Edible yield | I5: Walmart $ per 100 g edible | J5: BLS U.S. avg price ($) | K5: BLS unit (g) | L5: BLS $ per 100 g edible | M5: $ per 100 g USED | N5: Serving (g) | O5: Serving | P5: Max servings / day | Q5: Exclude? (Y) | R5: Must include (servings) | S5: Red meat | T5: Pork | U5: Poultry | V5: Fish | W5: Eggs | X5: Dairy | Y5: Gluten | Z5: Blocked by diet | AA5: Allowed (1/0) | AB5: Meal share: Breakfast | AC5: Meal share: Lunch | AD5: Meal share: Dinner | AE5: Meal share: Snacks | AF5: Grams per cup-equivalent | AG5: Group cap | AH5: Calories (kcal/100 g) | AI5: Protein (g/100 g) | AJ5: Carbohydrate (g/100 g) | AK5: Fat (g/100 g) | AL5: Fiber (g/100 g) | AM5: Total sugars (g/100 g) | AN5: Calcium (mg/100 g) | AO5: Iron (mg/100 g) | AP5: Potassium (mg/100 g) | AQ5: Sodium (mg/100 g) | AR5: Vitamin C (mg/100 g) | AS5: Protein per $ (g) | AT5: Calories per $ | AU5: USDA NDB # | AV5: USDA SR28 food | AW5: Price / data note
A6: 1 | B6: Proteins | C6: Poultry | D6: Chicken breast (boneless, skinless) | E6: Great Value frozen, 3 lb | F6: 9.84 | G6: 1360.8 | H6: 1 | I6: =F6/(G6*H6)*100 -> 0.72310406 | J6: 4.203 | K6: 453.6 | L6: =J6/(K6*H6)*100 -> 0.9265873 | M6: =IF(AND(IF(Planner!$C$39="BLS U.S. average (Sep 2026)",1,0)=1,L6<>""),L6,I6) -> 0.72310406 | N6: 113 | O6: 4 oz raw | P6: 2 | S6: 0 | T6: 0 | U6: 1 | V6: 0 | W6: 0 | X6: 0 | Y6: 0 | Z6: =SUMPRODUCT(S6:Y6,INDEX(Diets!$I$5:$O$12,MATCH(Planner!$C$36,Diets!$A$5:$A$12,0),0))+ISNUMBER(SEARCH(","&A6&",",","&SUBSTITUTE(INDEX(Diets!$P$5:$P$12,MATCH(Planner!$C$36,Diets!$A$5:$A$12,0))," ","")&","))*1 -> 0 | AA6: =IF(OR(UPPER(Q6)="Y",Z6>0),0,1) -> 1 | AB6: 0 | AC6: 0.5 | AD6: 0.5 | AE6: 0 | AG6: Meat, poultry & fish | AH6: 120 | AI6: 22.5 | AJ6: 0 | AK6: 2.62 | AL6: 0 | AM6: 0 | AN6: 5 | AO6: 0.37 | AP6: 334 | AQ6: 45 | AR6: 0 | AS6: =AI6/M6 -> 31.115854 | AT6: =AH6/M6 -> 165.95122 | AU6: 05062 | AV6: Chicken, broiler or fryers, breast, skinless, boneless, meat only, raw
A7: 2 | B7: Proteins | C7: Poultry | D7: Chicken drumsticks (bone-in) | E7: Great Value frozen, 4 lb | F7: 4.83 | G7: 1814.4 | H7: 0.67 | I7: =F7/(G7*H7)*100 -> 0.39731896 | J7: 1.739 | K7: 453.6 | L7: =J7/(K7*H7)*100 -> 0.57220511 | M7: =IF(AND(IF(Planner!$C$39="BLS U.S. average (Sep 2026)",1,0)=1,L7<>""),L7,I7) -> 0.39731896 | N7: 100 | O7: 100 g meat & skin (~1.5 drumsticks) | P7: 2 | S7: 0 | T7: 0 | U7: 1 | V7: 0 | W7: 0 | X7: 0 | Y7: 0 | Z7: =SUMPRODUCT(S7:Y7,INDEX(Diets!$I$5:$O$12,MATCH(Planner!$C$36,Diets!$A$5:$A$12,0),0))+ISNUMBER(SEARCH(","&A7&",",","&SUBSTITUTE(INDEX(Diets!$P$5:$P$12,MATCH(Planner!$C$36,Diets!$A$5:$A$12,0))," ","")&","))*1 -> 0 | AA7: =IF(OR(UPPER(Q7)="Y",Z7>0),0,1) -> 1 | AB7: 0 | AC7: 0.5 | AD7: 0.5 | AE7: 0 | AG7: Meat, poultry & fish | AH7: 161 | AI7: 18.08 | AJ7: 0.11 | AK7: 9.2 | AL7: 0 | AM7: 0 | AN7: 8 | AO7: 0.71 | AP7: 211 | AQ7: 106 | AR7: 0 | AS7: =AI7/M7 -> 45.505002 | AT7: =AH7/M7 -> 405.216 | AU7: 05066 | AV7: Chicken, broilers or fryers, drumstick, meat and skin, raw | AW7: Edible yield 67%: USDA lists bone twice (66%); 33% used; USDA refuse 66% (Bone and cartilage 33%, Bone and coonective tissue 33%) not applied: bought trimmed
A8: 3 | B8: Proteins | C8: Poultry | D8: Chicken thighs (boneless, skinless) | E8: Great Value frozen, 3 lb | F8: 9.87 | G8: 1360.8 | H8: 1 | I8: =F8/(G8*H8)*100 -> 0.72530864 | M8: =IF(AND(IF(Planner!$C$39="BLS U.S. average (Sep 2026)",1,0)=1,L8<>""),L8,I8) -> 0.72530864 | N8: 113 | O8: 4 oz raw | P8: 2 | S8: 0 | T8: 0 | U8: 1 | V8: 0 | W8: 0 | X8: 0 | Y8: 0 | Z8: =SUMPRODUCT(S8:Y8,INDEX(Diets!$I$5:$O$12,MATCH(Planner!$C$36,Diets!$A$5:$A$12,0),0))+ISNUMBER(SEARCH(","&A8&",",","&SUBSTITUTE(INDEX(Diets!$P$5:$P$12,MATCH(Planner!$C$36,Diets!$A$5:$A$12,0))," ","")&","))*1 -> 0 | AA8: =IF(OR(UPPER(Q8)="Y",Z8>0),0,1) -> 1 | AB8: 0 | AC8: 0.5 | AD8: 0.5 | AE8: 0 | AG8: Meat, poultry & fish | AH8: 121 | AI8: 19.66 | AJ8: 0 | AK8: 4.12 | AL8: 0 | AM8: 0 | AN8: 7 | AO8: 0.81 | AP8: 242 | AQ8: 95 | AR8: 0 | AS8: =AI8/M8 -> 27.105702 | AT8: =AH8/M8 -> 166.82553 | AU8: 05096 | AV8: Chicken, broilers or fryers, dark meat, thigh, meat only, raw | AW8: USDA refuse 25% ( Skin and separable fat 25%) not applied: bought trimmed
A9: 4 | B9: Proteins | C9: Poultry | D9: Deli turkey breast (sliced) | E9: Great Value thin sliced, 16 oz | F9: 5.97 | G9: 453.6 | H9: 1 | I9: =F9/(G9*H9)*100 -> 1.3161376 | M9: =IF(AND(IF(Planner!$C$39="BLS U.S. average (Sep 2026)",1,0)=1,L9<>""),L9,I9) -> 1.3161376 | N9: 56 | O9: 2 oz (about 4 slices) | P9: 2 | S9: 0 | T9: 0 | U9: 1 | V9: 0 | W9: 0 | X9: 0 | Y9: 0 | Z9: =SUMPRODUCT(S9:Y9,INDEX(Diets!$I$5:$O$12,MATCH(Planner!$C$36,Diets!$A$5:$A$12,0),0))+ISNUMBER(SEARCH(","&A9&",",","&SUBSTITUTE(INDEX(Diets!$P$5:$P$12,MATCH(Planner!$C$36,Diets!$A$5:$A$12,0))," ","")&","))*1 -> 0 | AA9: =IF(OR(UPPER(Q9)="Y",Z9>0),0,1) -> 1 | AB9: 0 | AC9: 1 | AD9: 0 | AE9: 0 | AG9: Meat, poultry & fish | AH9: 100 | AI9: 16.33 | AJ9: 2.34 | AK9: 2.37 | AL9: 0 | AM9: 3.28 | AN9: 7 | AO9: 0.34 | AP9: 401 | AQ9: 922 | AR9: 0 | AS9: =AI9/M9 -> 12.407518 | AT9: =AH9/M9 -> 75.979899 | AU9: 07081 | AV9: Turkey breast, sliced, prepackaged
A10: 5 | B10: Proteins | C10: Poultry | D10: Ground turkey 93/7 | E10: Jennie-O, 16 oz | F10: 5.56 | G10: 453.6 | H10: 1 | I10: =F10/(G10*H10)*100 -> 1.2257496 | M10: =IF(AND(IF(Planner!$C$39="BLS U.S. average (Sep 2026)",1,0)=1,L10<>""),L10,I10) -> 1.2257496 | N10: 113 | O10: 4 oz raw | P10: 2 | S10: 0 | T10: 0 | U10: 1 | V10: 0 | W10: 0 | X10: 0 | Y10: 0 | Z10: =SUMPRODUCT(S10:Y10,INDEX(Diets!$I$5:$O$12,MATCH(Planner!$C$36,Diets!$A$5:$A$12,0),0))+ISNUMBER(SEARCH(","&A10&",",","&SUBSTITUTE(INDEX(Diets!$P$5:$P$12,MATCH(Planner!$C$36,Diets!$A$5:$A$12,0))," ","")&","))*1 -> 0 | AA10: =IF(OR(UPPER(Q10)="Y",Z10>0),0,1) -> 1 | AB10: 0 | AC10: 0.5 | AD10: 0.5 | AE10: 0 | AG10: Meat, poultry & fish | AH10: 150 | AI10: 18.73 | AJ10: 0 | AK10: 8.34 | AL10: 0 | AM10: 0 | AN10: 21 | AO10: 1.17 | AP10: 213 | AQ10: 69 | AR10: 0 | AS10: =AI10/M10 -> 15.280446 | AT10: =AH10/M10 -> 122.3741 | AU10: 05665 | AV10: Ground turkey, 93% lean, 7% fat, raw
A11: 6 | B11: Proteins | C11: Red Meat & Pork | D11: Bacon | E11: Great Value hickory smoked, 16 oz | F11: 4.24 | G11: 453.6 | H11: 1 | I11: =F11/(G11*H11)*100 -> 0.93474427 | J11: 6.756 | K11: 453.6 | L11: =J11/(K11*H11)*100 -> 1.489418 | M11: =IF(AND(IF(Planner!$C$39="BLS U.S. average (Sep 2026)",1,0)=1,L11<>""),L11,I11) -> 0.93474427 | N11: 28 | O11: 1 slice raw | P11: 3 | S11: 1 | T11: 1 | U11: 0 | V11: 0 | W11: 0 | X11: 0 | Y11: 0 | Z11: =SUMPRODUCT(S11:Y11,INDEX(Diets!$I$5:$O$12,MATCH(Planner!$C$36,Diets!$A$5:$A$12,0),0))+ISNUMBER(SEARCH(","&A11&",",","&SUBSTITUTE(INDEX(Diets!$P$5:$P$12,MATCH(Planner!$C$36,Diets!$A$5:$A$12,0))," ","")&","))*1 -> 0 | AA11: =IF(OR(UPPER(Q11)="Y",Z11>0),0,1) -> 1 | AB11: 1 | AC11: 0 | AD11: 0 | AE11: 0 | AG11: Meat, poultry & fish | AH11: 417 | AI11: 12.62 | AJ11: 1.28 | AK11: 39.69 | AL11: 0 | AM11: 1 | AN11: 5 | AO11: 0.41 | AP11: 198 | AQ11: 662 | AR11: 0 | AS11: =AI11/M11 -> 13.501019 | AT11: =AH11/M11 -> 446.11132 | AU11: 10123 | AV11: Pork, cured, bacon, unprepared
A12: 7 | B12: Proteins | C12: Red Meat & Pork | D12: Ground beef 80/20 | E12: 80/20 ground chuck, 1 lb roll | F12: 6.43 | G12: 453.6 | H12: 1 | I12: =F12/(G12*H12)*100 -> 1.4175485 | J12: 6.792 | K12: 453.6 | L12: =J12/(K12*H12)*100 -> 1.4973545 | M12: =IF(AND(IF(Planner!$C$39="BLS U.S. average (Sep 2026)",1,0)=1,L12<>""),L12,I12) -> 1.4175485 | N12: 113 | O12: 4 oz raw | P12: 2 | S12: 1 | T12: 0 | U12: 0 | V12: 0 | W12: 0 | X12: 0 | Y12: 0 | Z12: =SUMPRODUCT(S12:Y12,INDEX(Diets!$I$5:$O$12,MATCH(Planner!$C$36,Diets!$A$5:$A$12,0),0))+ISNUMBER(SEARCH(","&A12&",",","&SUBSTITUTE(INDEX(Diets!$P$5:$P$12,MATCH(Planner!$C$36,Diets!$A$5:$A$12,0))," ","")&","))*1 -> 0 | AA12: =IF(OR(UPPER(Q12)="Y",Z12>0),0,1) -> 1 | AB12: 0 | AC12: 0.5 | AD12: 0.5 | AE12: 0 | AG12: Meat, poultry & fish | AH12: 254 | AI12: 17.17 | AJ12: 0 | AK12: 20 | AL12: 0 | AM12: 0 | AN12: 18 | AO12: 1.94 | AP12: 270 | AQ12: 66 | AR12: 0 | AS12: =AI12/M12 -> 12.11246 | AT12: =AH12/M12 -> 179.18258 | AU12: 23572 | AV12: Beef, ground, 80% lean meat / 20% fat, raw
A13: 8 | B13: Proteins | C13: Red Meat & Pork | D13: Ground beef 93/7 (lean) | E13: 93/7 lean ground beef, 1 lb | F13: 7.87 | G13: 453.6 | H13: 1 | I13: =F13/(G13*H13)*100 -> 1.7350088 | J13: 8.461 | K13: 453.6 | L13: =J13/(K13*H13)*100 -> 1.8652998 | M13: =IF(AND(IF(Planner!$C$39="BLS U.S. average (Sep 2026)",1,0)=1,L13<>""),L13,I13) -> 1.7350088 | N13: 113 | O13: 4 oz raw | P13: 2 | S13: 1 | T13: 0 | U13: 0 | V13: 0 | W13: 0 | X13: 0 | Y13: 0 | Z13: =SUMPRODUCT(S13:Y13,INDEX(Diets!$I$5:$O$12,MATCH(Planner!$C$36,Diets!$A$5:$A$12,0),0))+ISNUMBER(SEARCH(","&A13&",",","&SUBSTITUTE(INDEX(Diets!$P$5:$P$12,MATCH(Planner!$C$36,Diets!$A$5:$A$12,0))," ","")&","))*1 -> 0 | AA13: =IF(OR(UPPER(Q13)="Y",Z13>0),0,1) -> 1 | AB13: 0 | AC13: 0.5 | AD13: 0.5 | AE13: 0 | AG13: Meat, poultry & fish | AH13: 152 | AI13: 20.85 | AJ13: 0 | AK13: 7 | AL13: 0 | AM13: 0 | AN13: 10 | AO13: 2.33 | AP13: 336 | AQ13: 66 | AR13: 0 | AS13: =AI13/M13 -> 12.01723 | AT13: =AH13/M13 -> 87.607624 | AU13: 23472 | AV13: Beef, ground, 93% lean meat / 7% fat, raw
A14: 9 | B14: Proteins | C14: Red Meat & Pork | D14: Ham (sliced, cooked) | E14: Great Value cooked ham, 16 oz | F14: 4.97 | G14: 453.6 | H14: 1 | I14: =F14/(G14*H14)*100 -> 1.095679 | J14: 5.45 | K14: 453.6 | L14: =J14/(K14*H14)*100 -> 1.2014991 | M14: =IF(AND(IF(Planner!$C$39="BLS U.S. average (Sep 2026)",1,0)=1,L14<>""),L14,I14) -> 1.095679 | N14: 56 | O14: 2 oz (2 slices) | P14: 2 | S14: 1 | T14: 1 | U14: 0 | V14: 0 | W14: 0 | X14: 0 | Y14: 0 | Z14: =SUMPRODUCT(S14:Y14,INDEX(Diets!$I$5:$O$12,MATCH(Planner!$C$36,Diets!$A$5:$A$12,0),0))+ISNUMBER(SEARCH(","&A14&",",","&SUBSTITUTE(INDEX(Diets!$P$5:$P$12,MATCH(Planner!$C$36,Diets!$A$5:$A$12,0))," ","")&","))*1 -> 0 | AA14: =IF(OR(UPPER(Q14)="Y",Z14>0),0,1) -> 1 | AB14: 0 | AC14: 1 | AD14: 0 | AE14: 0 | AG14: Meat, poultry & fish | AH14: 163 | AI14: 16.6 | AJ14: 3.83 | AK14: 8.6 | AL14: 1.3 | AM14: 0 | AN14: 24 | AO14: 1.02 | AP14: 287 | AQ14: 1143 | AR14: 4 | AS14: =AI14/M14 -> 15.150423 | AT14: =AH14/M14 -> 148.7662 | AU14: 07029 | AV14: Ham, sliced, regular (approximately 11% fat) | AW14: Regular price; was on Rollback at $4.47
A15: 10 | B15: Proteins | C15: Red Meat & Pork | D15: Pork loin chops (boneless) | E15: Family pack, per lb | F15: 4.17 | G15: 453.6 | H15: 1 | I15: =F15/(G15*H15)*100 -> 0.91931217 | J15: 4.55 | K15: 453.6 | L15: =J15/(K15*H15)*100 -> 1.0030864 | M15: =IF(AND(IF(Planner!$C$39="BLS U.S. average (Sep 2026)",1,0)=1,L15<>""),L15,I15) -> 0.91931217 | N15: 113 | O15: 4 oz raw | P15: 2 | S15: 1 | T15: 1 | U15: 0 | V15: 0 | W15: 0 | X15: 0 | Y15: 0 | Z15: =SUMPRODUCT(S15:Y15,INDEX(Diets!$I$5:$O$12,MATCH(Planner!$C$36,Diets!$A$5:$A$12,0),0))+ISNUMBER(SEARCH(","&A15&",",","&SUBSTITUTE(INDEX(Diets!$P$5:$P$12,MATCH(Planner!$C$36,Diets!$A$5:$A$12,0))," ","")&","))*1 -> 0 | AA15: =IF(OR(UPPER(Q15)="Y",Z15>0),0,1) -> 1 | AB15: 0 | AC15: 0.5 | AD15: 0.5 | AE15: 0 | AG15: Meat, poultry & fish | AH15: 201 | AI15: 21.14 | AJ15: 0 | AK15: 12.96 | AL15: 0 | AM15: 0 | AN15: 9 | AO15: 0.48 | AP15: 345 | AQ15: 82 | AR15: 0 | AS15: =AI15/M15 -> 22.995453 | AT15: =AH15/M15 -> 218.64173 | AU15: 10164 | AV15: Pork, fresh, loin, center loin (chops), boneless, separable lean and fat, raw
A16: 11 | B16: Proteins | C16: Red Meat & Pork | D16: Top sirloin steak | E16: Choice Angus top sirloin, per lb | F16: 12.94 | G16: 453.6 | H16: 0.97 | I16: =F16/(G16*H16)*100 -> 2.9409626 | J16: 14.106 | K16: 453.6 | L16: =J16/(K16*H16)*100 -> 3.2059674 | M16: =IF(AND(IF(Planner!$C$39="BLS U.S. average (Sep 2026)",1,0)=1,L16<>""),L16,I16) -> 2.9409626 | N16: 113 | O16: 4 oz raw | P16: 2 | S16: 1 | T16: 0 | U16: 0 | V16: 0 | W16: 0 | X16: 0 | Y16: 0 | Z16: =SUMPRODUCT(S16:Y16,INDEX(Diets!$I$5:$O$12,MATCH(Planner!$C$36,Diets!$A$5:$A$12,0),0))+ISNUMBER(SEARCH(","&A16&",",","&SUBSTITUTE(INDEX(Diets!$P$5:$P$12,MATCH(Planner!$C$36,Diets!$A$5:$A$12,0))," ","")&","))*1 -> 0 | AA16: =IF(OR(UPPER(Q16)="Y",Z16>0),0,1) -> 1 | AB16: 0 | AC16: 0 | AD16: 1 | AE16: 0 | AG16: Meat, poultry & fish | AH16: 214 | AI16: 19.92 | AJ16: 0 | AK16: 14.28 | AL16: 0 | AM16: 0 | AN16: 25 | AO16: 1.46 | AP16: 309 | AQ16: 51 | AR16: 0 | AS16: =AI16/M16 -> 6.7732926 | AT16: =AH16/M16 -> 72.765292 | AU16: 13931 | AV16: Beef, top sirloin, steak, separable lean and fat, trimmed to 1/8" fat, choice, raw
A17: 12 | B17: Proteins | C17: Fish & Seafood | D17: Canned light tuna (in water) | E17: Great Value chunk light, 5 oz can | F17: 0.96 | G17: 141.7 | H17: 0.79 | I17: =F17/(G17*H17)*100 -> 0.8575793 | M17: =IF(AND(IF(Planner!$C$39="BLS U.S. average (Sep 2026)",1,0)=1,L17<>""),L17,I17) -> 0.8575793 | N17: 85 | O17: 3 oz drained | P17: 2 | S17: 0 | T17: 0 | U17: 0 | V17: 1 | W17: 0 | X17: 0 | Y17: 0 | Z17: =SUMPRODUCT(S17:Y17,INDEX(Diets!$I$5:$O$12,MATCH(Planner!$C$36,Diets!$A$5:$A$12,0),0))+ISNUMBER(SEARCH(","&A17&",",","&SUBSTITUTE(INDEX(Diets!$P$5:$P$12,MATCH(Planner!$C$36,Diets!$A$5:$A$12,0))," ","")&","))*1 -> 0 | AA17: =IF(OR(UPPER(Q17)="Y",Z17>0),0,1) -> 1 | AB17: 0 | AC17: 1 | AD17: 0 | AE17: 0 | AG17: Meat, poultry & fish | AH17: 86 | AI17: 19.44 | AJ17: 0 | AK17: 0.96 | AL17: 0 | AM17: 0 | AN17: 17 | AO17: 1.63 | AP17: 179 | AQ17: 247 | AR17: 0 | AS17: =AI17/M17 -> 22.668457 | AT17: =AH17/M17 -> 100.28227 | AU17: 15121 | AV17: Fish, tuna, light, canned in water, drained solids | AW17: Drained solids ~79% of can weight
A18: 13 | B18: Proteins | C18: Fish & Seafood | D18: Salmon (Atlantic, fillet) | E18: Marketside frozen portions, 2 lb | F18: 21.94 | G18: 907.2 | H18: 1 | I18: =F18/(G18*H18)*100 -> 2.4184303 | M18: =IF(AND(IF(Planner!$C$39="BLS U.S. average (Sep 2026)",1,0)=1,L18<>""),L18,I18) -> 2.4184303 | N18: 113 | O18: 4 oz raw | P18: 2 | S18: 0 | T18: 0 | U18: 0 | V18: 1 | W18: 0 | X18: 0 | Y18: 0 | Z18: =SUMPRODUCT(S18:Y18,INDEX(Diets!$I$5:$O$12,MATCH(Planner!$C$36,Diets!$A$5:$A$12,0),0))+ISNUMBER(SEARCH(","&A18&",",","&SUBSTITUTE(INDEX(Diets!$P$5:$P$12,MATCH(Planner!$C$36,Diets!$A$5:$A$12,0))," ","")&","))*1 -> 0 | AA18: =IF(OR(UPPER(Q18)="Y",Z18>0),0,1) -> 1 | AB18: 0 | AC18: 0 | AD18: 1 | AE18: 0 | AG18: Meat, poultry & fish | AH18: 208 | AI18: 20.42 | AJ18: 0 | AK18: 13.42 | AL18: 0 | AM18: 0 | AN18: 9 | AO18: 0.34 | AP18: 363 | AQ18: 59 | AR18: 3.9 | AS18: =AI18/M18 -> 8.4434932 | AT18: =AH18/M18 -> 86.006199 | AU18: 15236 | AV18: Fish, salmon, Atlantic, farmed, raw
A19: 14 | B19: Proteins | C19: Fish & Seafood | D19: Shrimp (raw, peeled) | E19: Great Value frozen, 2 lb | F19: 15.96 | G19: 907.2 | H19: 1 | I19: =F19/(G19*H19)*100 -> 1.7592593 | M19: =IF(AND(IF(Planner!$C$39="BLS U.S. average (Sep 2026)",1,0)=1,L19<>""),L19,I19) -> 1.7592593 | N19: 113 | O19: 4 oz raw | P19: 2 | S19: 0 | T19: 0 | U19: 0 | V19: 1 | W19: 0 | X19: 0 | Y19: 0 | Z19: =SUMPRODUCT(S19:Y19,INDEX(Diets!$I$5:$O$12,MATCH(Planner!$C$36,Diets!$A$5:$A$12,0),0))+ISNUMBER(SEARCH(","&A19&",",","&SUBSTITUTE(INDEX(Diets!$P$5:$P$12,MATCH(Planner!$C$36,Diets!$A$5:$A$12,0))," ","")&","))*1 -> 0 | AA19: =IF(OR(UPPER(Q19)="Y",Z19>0),0,1) -> 1 | AB19: 0 | AC19: 0 | AD19: 1 | AE19: 0 | AG19: Meat, poultry & fish | AH19: 71 | AI19: 13.61 | AJ19: 0.91 | AK19: 1.01 | AL19: 0 | AM19: 0 | AN19: 54 | AO19: 0.21 | AP19: 113 | AQ19: 566 | AR19: 0 | AS19: =AI19/M19 -> 7.7362105 | AT19: =AH19/M19 -> 40.357895 | AU19: 15149 | AV19: Crustaceans, shrimp, mixed species, raw (may have been previously frozen)
A20: 15 | B20: Proteins | C20: Fish & Seafood | D20: Tilapia (fillet) | E20: Great Value frozen, 2 lb | F20: 8.87 | G20: 907.2 | H20: 1 | I20: =F20/(G20*H20)*100 -> 0.97773369 | M20: =IF(AND(IF(Planner!$C$39="BLS U.S. average (Sep 2026)",1,0)=1,L20<>""),L20,I20) -> 0.97773369 | N20: 113 | O20: 4 oz raw | P20: 2 | S20: 0 | T20: 0 | U20: 0 | V20: 1 | W20: 0 | X20: 0 | Y20: 0 | Z20: =SUMPRODUCT(S20:Y20,INDEX(Diets!$I$5:$O$12,MATCH(Planner!$C$36,Diets!$A$5:$A$12,0),0))+ISNUMBER(SEARCH(","&A20&",",","&SUBSTITUTE(INDEX(Diets!$P$5:$P$12,MATCH(Planner!$C$36,Diets!$A$5:$A$12,0))," ","")&","))*1 -> 0 | AA20: =IF(OR(UPPER(Q20)="Y",Z20>0),0,1) -> 1 | AB20: 0 | AC20: 0.5 | AD20: 0.5 | AE20: 0 | AG20: Meat, poultry & fish | AH20: 96 | AI20: 20.08 | AJ20: 0 | AK20: 1.7 | AL20: 0 | AM20: 0 | AN20: 10 | AO20: 0.56 | AP20: 302 | AQ20: 52 | AR20: 0 | AS20: =AI20/M20 -> 20.53729 | AT20: =AH20/M20 -> 98.186246 | AU20: 15261 | AV20: Fish, tilapia, raw
A21: 16 | B21: Proteins | C21: Eggs | D21: Eggs (large) | E21: Great Value large, 12 ct | F21: 1.67 | G21: 681.8 | H21: 0.88 | I21: =F21/(G21*H21)*100 -> 0.27834076 | J21: 2.272 | K21: 681.8 | L21: =J21/(K21*H21)*100 -> 0.37867676 | M21: =IF(AND(IF(Planner!$C$39="BLS U.S. average (Sep 2026)",1,0)=1,L21<>""),L21,I21) -> 0.27834076 | N21: 50 | O21: 1 large egg | P21: 3 | S21: 0 | T21: 0 | U21: 0 | V21: 0 | W21: 1 | X21: 0 | Y21: 0 | Z21: =SUMPRODUCT(S21:Y21,INDEX(Diets!$I$5:$O$12,MATCH(Planner!$C$36,Diets!$A$5:$A$12,0),0))+ISNUMBER(SEARCH(","&A21&",",","&SUBSTITUTE(INDEX(Diets!$P$5:$P$12,MATCH(Planner!$C$36,Diets!$A$5:$A$12,0))," ","")&","))*1 -> 0 | AA21: =IF(OR(UPPER(Q21)="Y",Z21>0),0,1) -> 1 | AB21: 1 | AC21: 0 | AD21: 0 | AE21: 0 | AH21: 143 | AI21: 12.56 | AJ21: 0.72 | AK21: 9.51 | AL21: 0 | AM21: 0.37 | AN21: 56 | AO21: 1.75 | AP21: 138 | AQ21: 142 | AR21: 0 | AS21: =AI21/M21 -> 45.124545 | AT21: =AH21/M21 -> 513.75875 | AU21: 01123 | AV21: Egg, whole, raw, fresh | AW21: Dozen = 12 x 50 g edible; shell is 12% of weight
A22: 17 | B22: Proteins | C22: Plant Proteins | D22: Black beans (canned) | E22: Great Value no salt added, 15 oz | F22: 0.92 | G22: 425.2 | H22: 1 | I22: =F22/(G22*H22)*100 -> 0.21636877 | M22: =IF(AND(IF(Planner!$C$39="BLS U.S. average (Sep 2026)",1,0)=1,L22<>""),L22,I22) -> 0.21636877 | N22: 120 | O22: 1/2 cup | P22: 3 | S22: 0 | T22: 0 | U22: 0 | V22: 0 | W22: 0 | X22: 0 | Y22: 0 | Z22: =SUMPRODUCT(S22:Y22,INDEX(Diets!$I$5:$O$12,MATCH(Planner!$C$36,Diets!$A$5:$A$12,0),0))+ISNUMBER(SEARCH(","&A22&",",","&SUBSTITUTE(INDEX(Diets!$P$5:$P$12,MATCH(Planner!$C$36,Diets!$A$5:$A$12,0))," ","")&","))*1 -> 0 | AA22: =IF(OR(UPPER(Q22)="Y",Z22>0),0,1) -> 1 | AB22: 0 | AC22: 0.5 | AD22: 0.5 | AE22: 0 | AG22: Beans & lentils | AH22: 91 | AI22: 6.03 | AJ22: 16.55 | AK22: 0.29 | AL22: 6.9 | AM22: 0.23 | AN22: 35 | AO22: 1.9 | AP22: 308 | AQ22: 138 | AR22: 2.7 | AS22: =AI22/M22 -> 27.869087 | AT22: =AH22/M22 -> 420.57826 | AU22: 16316 | AV22: Beans, black, mature seeds, canned, low sodium | AW22: Nutrients for solids + liquid
A23: 18 | B23: Proteins | C23: Plant Proteins | D23: Chickpeas (canned) | E23: Great Value, 15.5 oz | F23: 0.92 | G23: 439.4 | H23: 1 | I23: =F23/(G23*H23)*100 -> 0.20937642 | M23: =IF(AND(IF(Planner!$C$39="BLS U.S. average (Sep 2026)",1,0)=1,L23<>""),L23,I23) -> 0.20937642 | N23: 120 | O23: 1/2 cup | P23: 3 | S23: 0 | T23: 0 | U23: 0 | V23: 0 | W23: 0 | X23: 0 | Y23: 0 | Z23: =SUMPRODUCT(S23:Y23,INDEX(Diets!$I$5:$O$12,MATCH(Planner!$C$36,Diets!$A$5:$A$12,0),0))+ISNUMBER(SEARCH(","&A23&",",","&SUBSTITUTE(INDEX(Diets!$P$5:$P$12,MATCH(Planner!$C$36,Diets!$A$5:$A$12,0))," ","")&","))*1 -> 0 | AA23: =IF(OR(UPPER(Q23)="Y",Z23>0),0,1) -> 1 | AB23: 0 | AC23: 0.5 | AD23: 0.5 | AE23: 0 | AG23: Beans & lentils | AH23: 88 | AI23: 4.92 | AJ23: 13.49 | AK23: 1.95 | AL23: 4.4 | AM23: 0 | AN23: 35 | AO23: 1.23 | AP23: 144 | AQ23: 278 | AR23: 0.1 | AS23: =AI23/M23 -> 23.498348 | AT23: =AH23/M23 -> 420.29565 | AU23: 16058 | AV23: Chickpeas (garbanzo beans, bengal gram), mature seeds, canned, solids and liquids | AW23: Nutrients for solids + liquid
A24: 19 | B24: Proteins | C24: Plant Proteins | D24: Lentils (dry) | E24: Great Value, 1 lb | F24: 1.92 | G24: 453.6 | H24: 1 | I24: =F24/(G24*H24)*100 -> 0.42328042 | M24: =IF(AND(IF(Planner!$C$39="BLS U.S. average (Sep 2026)",1,0)=1,L24<>""),L24,I24) -> 0.42328042 | N24: 48 | O24: 1/4 cup dry (~3/4 cup cooked) | P24: 3 | S24: 0 | T24: 0 | U24: 0 | V24: 0 | W24: 0 | X24: 0 | Y24: 0 | Z24: =SUMPRODUCT(S24:Y24,INDEX(Diets!$I$5:$O$12,MATCH(Planner!$C$36,Diets!$A$5:$A$12,0),0))+ISNUMBER(SEARCH(","&A24&",",","&SUBSTITUTE(INDEX(Diets!$P$5:$P$12,MATCH(Planner!$C$36,Diets!$A$5:$A$12,0))," ","")&","))*1 -> 0 | AA24: =IF(OR(UPPER(Q24)="Y",Z24>0),0,1) -> 1 | AB24: 0 | AC24: 0.5 | AD24: 0.5 | AE24: 0 | AG24: Beans & lentils | AH24: 352 | AI24: 24.63 | AJ24: 63.35 | AK24: 1.06 | AL24: 10.7 | AM24: 2.03 | AN24: 35 | AO24: 6.51 | AP24: 677 | AQ24: 6 | AR24: 4.5 | AS24: =AI24/M24 -> 58.188375 | AT24: =AH24/M24 -> 831.6 | AU24: 16069 | AV24: Lentils, raw
A25: 20 | B25: Proteins | C25: Plant Proteins | D25: Peanut butter | E25: Great Value creamy, 40 oz | F25: 3.98 | G25: 1134 | H25: 1 | I25: =F25/(G25*H25)*100 -> 0.35097002 | M25: =IF(AND(IF(Planner!$C$39="BLS U.S. average (Sep 2026)",1,0)=1,L25<>""),L25,I25) -> 0.35097002 | N25: 32 | O25: 2 tbsp | P25: 2 | S25: 0 | T25: 0 | U25: 0 | V25: 0 | W25: 0 | X25: 0 | Y25: 0 | Z25: =SUMPRODUCT(S25:Y25,INDEX(Diets!$I$5:$O$12,MATCH(Planner!$C$36,Diets!$A$5:$A$12,0),0))+ISNUMBER(SEARCH(","&A25&",",","&SUBSTITUTE(INDEX(Diets!$P$5:$P$12,MATCH(Planner!$C$36,Diets!$A$5:$A$12,0))," ","")&","))*1 -> 0 | AA25: =IF(OR(UPPER(Q25)="Y",Z25>0),0,1) -> 1 | AB25: 0.5 | AC25: 0 | AD25: 0 | AE25: 0.5 | AH25: 598 | AI25: 22.21 | AJ25: 22.31 | AK25: 51.36 | AL25: 5 | AM25: 10.49 | AN25: 49 | AO25: 1.74 | AP25: 558 | AQ25: 426 | AR25: 0 | AS25: =AI25/M25 -> 63.281759 | AT25: =AH25/M25 -> 1703.8492 | AU25: 16098 | AV25: Peanut butter, smooth style, with salt
A26: 21 | B26: Proteins | C26: Plant Proteins | D26: Pinto beans (dry) | E26: Great Value, 2 lb | F26: 1.98 | G26: 907.2 | H26: 1 | I26: =F26/(G26*H26)*100 -> 0.21825397 | J26: 1.669 | K26: 453.6 | L26: =J26/(K26*H26)*100 -> 0.36794533 | M26: =IF(AND(IF(Planner!$C$39="BLS U.S. average (Sep 2026)",1,0)=1,L26<>""),L26,I26) -> 0.21825397 | N26: 48 | O26: 1/4 cup dry (~3/4 cup cooked) | P26: 3 | S26: 0 | T26: 0 | U26: 0 | V26: 0 | W26: 0 | X26: 0 | Y26: 0 | Z26: =SUMPRODUCT(S26:Y26,INDEX(Diets!$I$5:$O$12,MATCH(Planner!$C$36,Diets!$A$5:$A$12,0),0))+ISNUMBER(SEARCH(","&A26&",",","&SUBSTITUTE(INDEX(Diets!$P$5:$P$12,MATCH(Planner!$C$36,Diets!$A$5:$A$12,0))," ","")&","))*1 -> 0 | AA26: =IF(OR(UPPER(Q26)="Y",Z26>0),0,1) -> 1 | AB26: 0 | AC26: 0.5 | AD26: 0.5 | AE26: 0 | AG26: Beans & lentils | AH26: 347 | AI26: 21.42 | AJ26: 62.55 | AK26: 1.23 | AL26: 15.5 | AM26: 2.11 | AN26: 113 | AO26: 5.07 | AP26: 1393 | AQ26: 12 | AR26: 6.3 | AS26: =AI26/M26 -> 98.142545 | AT26: =AH26/M26 -> 1589.8909 | AU26: 16042 | AV26: Beans, pinto, mature seeds, raw
A27: 22 | B27: Proteins | C27: Plant Proteins | D27: Tofu (extra firm) | E27: Nasoya extra firm, 14 oz | F27: 2.97 | G27: 396.9 | H27: 1 | I27: =F27/(G27*H27)*100 -> 0.74829932 | M27: =IF(AND(IF(Planner!$C$39="BLS U.S. average (Sep 2026)",1,0)=1,L27<>""),L27,I27) -> 0.74829932 | N27: 85 | O27: 3 oz | P27: 3 | S27: 0 | T27: 0 | U27: 0 | V27: 0 | W27: 0 | X27: 0 | Y27: 0 | Z27: =SUMPRODUCT(S27:Y27,INDEX(Diets!$I$5:$O$12,MATCH(Planner!$C$36,Diets!$A$5:$A$12,0),0))+ISNUMBER(SEARCH(","&A27&",",","&SUBSTITUTE(INDEX(Diets!$P$5:$P$12,MATCH(Planner!$C$36,Diets!$A$5:$A$12,0))," ","")&","))*1 -> 0 | AA27: =IF(OR(UPPER(Q27)="Y",Z27>0),0,1) -> 1 | AB27: 0 | AC27: 0.5 | AD27: 0.5 | AE27: 0 | AH27: 98 | AI27: 10.1 | AJ27: 2.6 | AK27: 5.2 | AL27: 1.3 | AM27: 0.4 | AN27: 77 | AO27: 1.6 | AP27: 0 | AQ27: 4 | AR27: 0 | AS27: =AI27/M27 -> 13.497273 | AT27: =AH27/M27 -> 130.96364 | AU27: 16212 | AV27: Vitasoy USA, Organic Nasoya Extra Firm Tofu | AW27: Price undated (Walmart Business listing)
A28: 23 | B28: Dairy & Alternatives | C28: Milk & Yogurt | D28: 2% milk | E28: Great Value, 1 gal | F28: 3.31 | G28: 3904 | H28: 1 | I28: =F28/(G28*H28)*100 -> 0.084784836 | M28: =IF(AND(IF(Planner!$C$39="BLS U.S. average (Sep 2026)",1,0)=1,L28<>""),L28,I28) -> 0.084784836 | N28: 244 | O28: 1 cup | P28: 3 | S28: 0 | T28: 0 | U28: 0 | V28: 0 | W28: 0 | X28: 1 | Y28: 0 | Z28: =SUMPRODUCT(S28:Y28,INDEX(Diets!$I$5:$O$12,MATCH(Planner!$C$36,Diets!$A$5:$A$12,0),0))+ISNUMBER(SEARCH(","&A28&",",","&SUBSTITUTE(INDEX(Diets!$P$5:$P$12,MATCH(Planner!$C$36,Diets!$A$5:$A$12,0))," ","")&","))*1 -> 0 | AA28: =IF(OR(UPPER(Q28)="Y",Z28>0),0,1) -> 1 | AB28: 0.5 | AC28: 0 | AD28: 0 | AE28: 0.5 | AH28: 50 | AI28: 3.3 | AJ28: 4.8 | AK28: 1.98 | AL28: 0 | AM28: 5.06 | AN28: 120 | AO28: 0.02 | AP28: 140 | AQ28: 47 | AR28: 0.2 | AS28: =AI28/M28 -> 38.922054 | AT28: =AH28/M28 -> 589.7281 | AU28: 01079 | AV28: Milk, reduced fat, fluid, 2% milkfat, with added vitamin A and vitamin D | AW28: Gallon = 16 cups x 244 g
A29: 24 | B29: Dairy & Alternatives | C29: Milk & Yogurt | D29: Greek yogurt (plain, nonfat) | E29: Great Value, 32 oz | F29: 3.28 | G29: 907.2 | H29: 1 | I29: =F29/(G29*H29)*100 -> 0.36155203 | M29: =IF(AND(IF(Planner!$C$39="BLS U.S. average (Sep 2026)",1,0)=1,L29<>""),L29,I29) -> 0.36155203 | N29: 170 | O29: 1 container (6 oz) | P29: 2 | S29: 0 | T29: 0 | U29: 0 | V29: 0 | W29: 0 | X29: 1 | Y29: 0 | Z29: =SUMPRODUCT(S29:Y29,INDEX(Diets!$I$5:$O$12,MATCH(Planner!$C$36,Diets!$A$5:$A$12,0),0))+ISNUMBER(SEARCH(","&A29&",",","&SUBSTITUTE(INDEX(Diets!$P$5:$P$12,MATCH(Planner!$C$36,Diets!$A$5:$A$12,0))," ","")&","))*1 -> 0 | AA29: =IF(OR(UPPER(Q29)="Y",Z29>0),0,1) -> 1 | AB29: 0.5 | AC29: 0 | AD29: 0 | AE29: 0.5 | AH29: 59 | AI29: 10.19 | AJ29: 3.6 | AK29: 0.39 | AL29: 0 | AM29: 3.24 | AN29: 110 | AO29: 0.07 | AP29: 141 | AQ29: 36 | AR29: 0 | AS29: =AI29/M29 -> 28.184049 | AT29: =AH29/M29 -> 163.18537 | AU29: 01256 | AV29: Yogurt, Greek, plain, nonfat
A30: 25 | B30: Dairy & Alternatives | C30: Milk & Yogurt | D30: Soy milk (calcium-fortified) | E30: Silk original, 64 fl oz | F30: 4.57 | G30: 1944 | H30: 1 | I30: =F30/(G30*H30)*100 -> 0.2350823 | M30: =IF(AND(IF(Planner!$C$39="BLS U.S. average (Sep 2026)",1,0)=1,L30<>""),L30,I30) -> 0.2350823 | N30: 243 | O30: 1 cup | P30: 3 | S30: 0 | T30: 0 | U30: 0 | V30: 0 | W30: 0 | X30: 0 | Y30: 0 | Z30: =SUMPRODUCT(S30:Y30,INDEX(Diets!$I$5:$O$12,MATCH(Planner!$C$36,Diets!$A$5:$A$12,0),0))+ISNUMBER(SEARCH(","&A30&",",","&SUBSTITUTE(INDEX(Diets!$P$5:$P$12,MATCH(Planner!$C$36,Diets!$A$5:$A$12,0))," ","")&","))*1 -> 0 | AA30: =IF(OR(UPPER(Q30)="Y",Z30>0),0,1) -> 1 | AB30: 0.5 | AC30: 0 | AD30: 0 | AE30: 0.5 | AH30: 43 | AI30: 2.6 | AJ30: 4.92 | AK30: 1.47 | AL30: 0.2 | AM30: 3.65 | AN30: 123 | AO30: 0.42 | AP30: 122 | AQ30: 47 | AR30: 0 | AS30: =AI30/M30 -> 11.059956 | AT30: =AH30/M30 -> 182.91466 | AU30: 16139 | AV30: Soymilk, original and vanilla, with added calcium, vitamins A and D | AW30: Half gallon = 8 cups x 243 g
A31: 26 | B31: Dairy & Alternatives | C31: Milk & Yogurt | D31: Whole milk | E31: Great Value, 1 gal | F31: 3.48 | G31: 3904 | H31: 1 | I31: =F31/(G31*H31)*100 -> 0.089139344 | J31: 4.106 | K31: 3904 | L31: =J31/(K31*H31)*100 -> 0.10517418 | M31: =IF(AND(IF(Planner!$C$39="BLS U.S. average (Sep 2026)",1,0)=1,L31<>""),L31,I31) -> 0.089139344 | N31: 244 | O31: 1 cup | P31: 3 | S31: 0 | T31: 0 | U31: 0 | V31: 0 | W31: 0 | X31: 1 | Y31: 0 | Z31: =SUMPRODUCT(S31:Y31,INDEX(Diets!$I$5:$O$12,MATCH(Planner!$C$36,Diets!$A$5:$A$12,0),0))+ISNUMBER(SEARCH(","&A31&",",","&SUBSTITUTE(INDEX(Diets!$P$5:$P$12,MATCH(Planner!$C$36,Diets!$A$5:$A$12,0))," ","")&","))*1 -> 0 | AA31: =IF(OR(UPPER(Q31)="Y",Z31>0),0,1) -> 1 | AB31: 0.5 | AC31: 0 | AD31: 0 | AE31: 0.5 | AH31: 61 | AI31: 3.15 | AJ31: 4.8 | AK31: 3.25 | AL31: 0 | AM31: 5.05 | AN31: 113 | AO31: 0.03 | AP31: 132 | AQ31: 43 | AR31: 0 | AS31: =AI31/M31 -> 35.337931 | AT31: =AH31/M31 -> 684.32184 | AU31: 01077 | AV31: Milk, whole, 3.25% milkfat, with added vitamin D | AW31: Gallon = 16 cups x 244 g
A32: 27 | B32: Dairy & Alternatives | C32: Cheese | D32: American cheese (singles) | E32: Great Value, 16 oz / 24 slices | F32: 2.48 | G32: 453.6 | H32: 1 | I32: =F32/(G32*H32)*100 -> 0.54673721 | J32: 4.737 | K32: 453.6 | L32: =J32/(K32*H32)*100 -> 1.0443122 | M32: =IF(AND(IF(Planner!$C$39="BLS U.S. average (Sep 2026)",1,0)=1,L32<>""),L32,I32) -> 0.54673721 | N32: 19 | O32: 1 slice | P32: 3 | S32: 0 | T32: 0 | U32: 0 | V32: 0 | W32: 0 | X32: 1 | Y32: 0 | Z32: =SUMPRODUCT(S32:Y32,INDEX(Diets!$I$5:$O$12,MATCH(Planner!$C$36,Diets!$A$5:$A$12,0),0))+ISNUMBER(SEARCH(","&A32&",",","&SUBSTITUTE(INDEX(Diets!$P$5:$P$12,MATCH(Planner!$C$36,Diets!$A$5:$A$12,0))," ","")&","))*1 -> 0 | AA32: =IF(OR(UPPER(Q32)="Y",Z32>0),0,1) -> 1 | AB32: 0 | AC32: 1 | AD32: 0 | AE32: 0 | AG32: Cheese | AH32: 366 | AI32: 18.13 | AJ32: 4.78 | AK32: 30.71 | AL32: 0 | AM32: 2.26 | AN32: 1045 | AO32: 0.63 | AP32: 132 | AQ32: 1671 | AR32: 0 | AS32: =AI32/M32 -> 33.160355 | AT32: =AH32/M32 -> 669.42581 | AU32: 01042 | AV32: Cheese, pasteurized process, American, fortified with vitamin D
A33: 28 | B33: Dairy & Alternatives | C33: Cheese | D33: Cheddar cheese | E33: Great Value medium block, 8 oz | F33: 1.87 | G33: 226.8 | H33: 1 | I33: =F33/(G33*H33)*100 -> 0.82451499 | J33: 6.133 | K33: 453.6 | L33: =J33/(K33*H33)*100 -> 1.3520723 | M33: =IF(AND(IF(Planner!$C$39="BLS U.S. average (Sep 2026)",1,0)=1,L33<>""),L33,I33) -> 0.82451499 | N33: 28 | O33: 1 oz | P33: 2 | S33: 0 | T33: 0 | U33: 0 | V33: 0 | W33: 0 | X33: 1 | Y33: 0 | Z33: =SUMPRODUCT(S33:Y33,INDEX(Diets!$I$5:$O$12,MATCH(Planner!$C$36,Diets!$A$5:$A$12,0),0))+ISNUMBER(SEARCH(","&A33&",",","&SUBSTITUTE(INDEX(Diets!$P$5:$P$12,MATCH(Planner!$C$36,Diets!$A$5:$A$12,0))," ","")&","))*1 -> 0 | AA33: =IF(OR(UPPER(Q33)="Y",Z33>0),0,1) -> 1 | AB33: 0 | AC33: 0.5 | AD33: 0.5 | AE33: 0 | AG33: Cheese | AH33: 404 | AI33: 22.87 | AJ33: 3.09 | AK33: 33.31 | AL33: 0 | AM33: 0.48 | AN33: 710 | AO33: 0.14 | AP33: 76 | AQ33: 653 | AR33: 0 | AS33: =AI33/M33 -> 27.737519 | AT33: =AH33/M33 -> 489.98503 | AU33: 01009 | AV33: Cheese, cheddar
A34: 29 | B34: Dairy & Alternatives | C34: Cheese | D34: Cottage cheese (2%) | E34: Great Value small curd, 24 oz | F34: 2.87 | G34: 680.4 | H34: 1 | I34: =F34/(G34*H34)*100 -> 0.4218107 | M34: =IF(AND(IF(Planner!$C$39="BLS U.S. average (Sep 2026)",1,0)=1,L34<>""),L34,I34) -> 0.4218107 | N34: 113 | O34: 1/2 cup | P34: 2 | S34: 0 | T34: 0 | U34: 0 | V34: 0 | W34: 0 | X34: 1 | Y34: 0 | Z34: =SUMPRODUCT(S34:Y34,INDEX(Diets!$I$5:$O$12,MATCH(Planner!$C$36,Diets!$A$5:$A$12,0),0))+ISNUMBER(SEARCH(","&A34&",",","&SUBSTITUTE(INDEX(Diets!$P$5:$P$12,MATCH(Planner!$C$36,Diets!$A$5:$A$12,0))," ","")&","))*1 -> 0 | AA34: =IF(OR(UPPER(Q34)="Y",Z34>0),0,1) -> 1 | AB34: 0 | AC34: 0.5 | AD34: 0 | AE34: 0.5 | AG34: Cheese | AH34: 81 | AI34: 10.45 | AJ34: 4.76 | AK34: 2.27 | AL34: 0 | AM34: 4 | AN34: 111 | AO34: 0.13 | AP34: 125 | AQ34: 308 | AR34: 0 | AS34: =AI34/M34 -> 24.774146 | AT34: =AH34/M34 -> 192.02927 | AU34: 01015 | AV34: Cheese, cottage, lowfat, 2% milkfat
A35: 30 | B35: Dairy & Alternatives | C35: Cheese | D35: Mozzarella string cheese | E35: Great Value part-skim, 12 ct | F35: 3.28 | G35: 340.2 | H35: 1 | I35: =F35/(G35*H35)*100 -> 0.96413874 | M35: =IF(AND(IF(Planner!$C$39="BLS U.S. average (Sep 2026)",1,0)=1,L35<>""),L35,I35) -> 0.96413874 | N35: 28 | O35: 1 stick | P35: 2 | S35: 0 | T35: 0 | U35: 0 | V35: 0 | W35: 0 | X35: 1 | Y35: 0 | Z35: =SUMPRODUCT(S35:Y35,INDEX(Diets!$I$5:$O$12,MATCH(Planner!$C$36,Diets!$A$5:$A$12,0),0))+ISNUMBER(SEARCH(","&A35&",",","&SUBSTITUTE(INDEX(Diets!$P$5:$P$12,MATCH(Planner!$C$36,Diets!$A$5:$A$12,0))," ","")&","))*1 -> 0 | AA35: =IF(OR(UPPER(Q35)="Y",Z35>0),0,1) -> 1 | AB35: 0 | AC35: 0 | AD35: 0 | AE35: 1 | AG35: Cheese | AH35: 295 | AI35: 23.75 | AJ35: 5.58 | AK35: 19.78 | AL35: 0 | AM35: 1.9 | AN35: 697 | AO35: 0.22 | AP35: 188 | AQ35: 666 | AR35: 0 | AS35: =AI35/M35 -> 24.633384 | AT35: =AH35/M35 -> 305.97256 | AU35: 01029 | AV35: Cheese, mozzarella, low moisture, part-skim | AW35: Price undated (Walmart.com listing)
A36: 31 | B36: Carbohydrates | C36: Grains & Bread | D36: Bagels (plain) | E36: Great Value, 6 ct / 20 oz | F36: 2.14 | G36: 567 | H36: 1 | I36: =F36/(G36*H36)*100 -> 0.37742504 | M36: =IF(AND(IF(Planner!$C$39="BLS U.S. average (Sep 2026)",1,0)=1,L36<>""),L36,I36) -> 0.37742504 | N36: 94 | O36: 1 bagel | P36: 1 | S36: 0 | T36: 0 | U36: 0 | V36: 0 | W36: 0 | X36: 0 | Y36: 1 | Z36: =SUMPRODUCT(S36:Y36,INDEX(Diets!$I$5:$O$12,MATCH(Planner!$C$36,Diets!$A$5:$A$12,0),0))+ISNUMBER(SEARCH(","&A36&",",","&SUBSTITUTE(INDEX(Diets!$P$5:$P$12,MATCH(Planner!$C$36,Diets!$A$5:$A$12,0))," ","")&","))*1 -> 0 | AA36: =IF(OR(UPPER(Q36)="Y",Z36>0),0,1) -> 1 | AB36: 1 | AC36: 0 | AD36: 0 | AE36: 0 | AG36: Grains & bread | AH36: 264 | AI36: 10.56 | AJ36: 52.38 | AK36: 1.32 | AL36: 1.6 | AM36: 8.43 | AN36: 219 | AO36: 3.57 | AP36: 107 | AQ36: 422 | AR36: 0 | AS36: =AI36/M36 -> 27.979065 | AT36: =AH36/M36 -> 699.47664 | AU36: 18001 | AV36: Bagels, plain, enriched, with calcium propionate (includes onion, poppy, sesame)
A37: 32 | B37: Carbohydrates | C37: Grains & Bread | D37: Brown rice (dry) | E37: Great Value long grain, 32 oz | F37: 1.72 | G37: 907.2 | H37: 1 | I37: =F37/(G37*H37)*100 -> 0.18959436 | M37: =IF(AND(IF(Planner!$C$39="BLS U.S. average (Sep 2026)",1,0)=1,L37<>""),L37,I37) -> 0.18959436 | N37: 46 | O37: 1/4 cup dry (~3/4 cup cooked) | P37: 4 | S37: 0 | T37: 0 | U37: 0 | V37: 0 | W37: 0 | X37: 0 | Y37: 0 | Z37: =SUMPRODUCT(S37:Y37,INDEX(Diets!$I$5:$O$12,MATCH(Planner!$C$36,Diets!$A$5:$A$12,0),0))+ISNUMBER(SEARCH(","&A37&",",","&SUBSTITUTE(INDEX(Diets!$P$5:$P$12,MATCH(Planner!$C$36,Diets!$A$5:$A$12,0))," ","")&","))*1 -> 0 | AA37: =IF(OR(UPPER(Q37)="Y",Z37>0),0,1) -> 1 | AB37: 0 | AC37: 0.5 | AD37: 0.5 | AE37: 0 | AG37: Grains & bread | AH37: 367 | AI37: 7.54 | AJ37: 76.25 | AK37: 3.2 | AL37: 3.6 | AM37: 0.66 | AN37: 9 | AO37: 1.29 | AP37: 250 | AQ37: 5 | AR37: 0 | AS37: =AI37/M37 -> 39.769116 | AT37: =AH37/M37 -> 1935.7116 | AU37: 20036 | AV37: Rice, brown, long-grain, raw
A38: 33 | B38: Carbohydrates | C38: Grains & Bread | D38: Cheerios | E38: Cheerios family size, 18 oz | F38: 4.97 | G38: 510.3 | H38: 1 | I38: =F38/(G38*H38)*100 -> 0.9739369 | M38: =IF(AND(IF(Planner!$C$39="BLS U.S. average (Sep 2026)",1,0)=1,L38<>""),L38,I38) -> 0.9739369 | N38: 28 | O38: 1 cup | P38: 2 | S38: 0 | T38: 0 | U38: 0 | V38: 0 | W38: 0 | X38: 0 | Y38: 0 | Z38: =SUMPRODUCT(S38:Y38,INDEX(Diets!$I$5:$O$12,MATCH(Planner!$C$36,Diets!$A$5:$A$12,0),0))+ISNUMBER(SEARCH(","&A38&",",","&SUBSTITUTE(INDEX(Diets!$P$5:$P$12,MATCH(Planner!$C$36,Diets!$A$5:$A$12,0))," ","")&","))*1 -> 0 | AA38: =IF(OR(UPPER(Q38)="Y",Z38>0),0,1) -> 1 | AB38: 1 | AC38: 0 | AD38: 0 | AE38: 0 | AG38: Grains & bread | AH38: 376 | AI38: 12.09 | AJ38: 73.23 | AK38: 6.73 | AL38: 9.4 | AM38: 4.36 | AN38: 401 | AO38: 33.17 | AP38: 641 | AQ38: 497 | AR38: 21.6 | AS38: =AI38/M38 -> 12.413535 | AT38: =AH38/M38 -> 386.06197 | AU38: 08013 | AV38: Cereals ready-to-eat, GENERAL MILLS, CHEERIOS | AW38: Regular price; was on Rollback at $4.50
A39: 34 | B39: Carbohydrates | C39: Grains & Bread | D39: Corn tortillas | E39: Mission yellow corn, 30 ct | F39: 2.48 | G39: 791 | H39: 1 | I39: =F39/(G39*H39)*100 -> 0.31352718 | M39: =IF(AND(IF(Planner!$C$39="BLS U.S. average (Sep 2026)",1,0)=1,L39<>""),L39,I39) -> 0.31352718 | N39: 26 | O39: 1 tortilla | P39: 6 | S39: 0 | T39: 0 | U39: 0 | V39: 0 | W39: 0 | X39: 0 | Y39: 0 | Z39: =SUMPRODUCT(S39:Y39,INDEX(Diets!$I$5:$O$12,MATCH(Planner!$C$36,Diets!$A$5:$A$12,0),0))+ISNUMBER(SEARCH(","&A39&",",","&SUBSTITUTE(INDEX(Diets!$P$5:$P$12,MATCH(Planner!$C$36,Diets!$A$5:$A$12,0))," ","")&","))*1 -> 0 | AA39: =IF(OR(UPPER(Q39)="Y",Z39>0),0,1) -> 1 | AB39: 0 | AC39: 0.5 | AD39: 0.5 | AE39: 0 | AG39: Grains & bread | AH39: 218 | AI39: 5.7 | AJ39: 44.64 | AK39: 2.85 | AL39: 6.3 | AM39: 0.88 | AN39: 81 | AO39: 1.23 | AP39: 186 | AQ39: 45 | AR39: 0 | AS39: =AI39/M39 -> 18.180242 | AT39: =AH39/M39 -> 695.31452 | AU39: 18363 | AV39: Tortillas, ready-to-bake or -fry, corn | AW39: Weight from listed unit price (8.9 cents/oz)
A40: 35 | B40: Carbohydrates | C40: Grains & Bread | D40: Flour tortillas | E40: Great Value medium, 10 ct / 16 oz | F40: 1.98 | G40: 453.6 | H40: 1 | I40: =F40/(G40*H40)*100 -> 0.43650794 | M40: =IF(AND(IF(Planner!$C$39="BLS U.S. average (Sep 2026)",1,0)=1,L40<>""),L40,I40) -> 0.43650794 | N40: 45 | O40: 1 tortilla | P40: 3 | S40: 0 | T40: 0 | U40: 0 | V40: 0 | W40: 0 | X40: 0 | Y40: 1 | Z40: =SUMPRODUCT(S40:Y40,INDEX(Diets!$I$5:$O$12,MATCH(Planner!$C$36,Diets!$A$5:$A$12,0),0))+ISNUMBER(SEARCH(","&A40&",",","&SUBSTITUTE(INDEX(Diets!$P$5:$P$12,MATCH(Planner!$C$36,Diets!$A$5:$A$12,0))," ","")&","))*1 -> 0 | AA40: =IF(OR(UPPER(Q40)="Y",Z40>0),0,1) -> 1 | AB40: 0 | AC40: 0.5 | AD40: 0.5 | AE40: 0 | AG40: Grains & bread | AH40: 297 | AI40: 8.01 | AJ40: 49.27 | AK40: 7.58 | AL40: 2.4 | AM40: 2.66 | AN40: 163 | AO40: 3.32 | AP40: 133 | AQ40: 742 | AR40: 0 | AS40: =AI40/M40 -> 18.350182 | AT40: =AH40/M40 -> 680.4 | AU40: 18970 | AV40: Tortillas, ready-to-bake or -fry, flour, shelf stable
A41: 36 | B41: Carbohydrates | C41: Grains & Bread | D41: Quinoa (dry) | E41: Great Value organic, 16 oz | F41: 3.44 | G41: 453.6 | H41: 1 | I41: =F41/(G41*H41)*100 -> 0.75837743 | M41: =IF(AND(IF(Planner!$C$39="BLS U.S. average (Sep 2026)",1,0)=1,L41<>""),L41,I41) -> 0.75837743 | N41: 43 | O41: 1/4 cup dry (~3/4 cup cooked) | P41: 3 | S41: 0 | T41: 0 | U41: 0 | V41: 0 | W41: 0 | X41: 0 | Y41: 0 | Z41: =SUMPRODUCT(S41:Y41,INDEX(Diets!$I$5:$O$12,MATCH(Planner!$C$36,Diets!$A$5:$A$12,0),0))+ISNUMBER(SEARCH(","&A41&",",","&SUBSTITUTE(INDEX(Diets!$P$5:$P$12,MATCH(Planner!$C$36,Diets!$A$5:$A$12,0))," ","")&","))*1 -> 0 | AA41: =IF(OR(UPPER(Q41)="Y",Z41>0),0,1) -> 1 | AB41: 0 | AC41: 0.5 | AD41: 0.5 | AE41: 0 | AG41: Grains & bread | AH41: 368 | AI41: 14.12 | AJ41: 64.16 | AK41: 6.07 | AL41: 7 | AM41: 0 | AN41: 47 | AO41: 4.57 | AP41: 563 | AQ41: 5 | AR41: 0 | AS41: =AI41/M41 -> 18.618698 | AT41: =AH41/M41 -> 485.24651 | AU41: 20035 | AV41: Quinoa, uncooked
...

Sheet Diets
A1: Diets — macro split and which food attributes each diet forbids
A2: Food j is allowed when (attribute row of food j) · (forbidden row of the diet) = 0 and j is not in "Also excluded". Source: config/diets.json (edit there; this sheet is rebuilt from it).
A4: Diet | B4: Description | C4: Protein min | D4: Protein max | E4: Carbs min | F4: Carbs max | G4: Fat min | H4: Fat max | I4: Forbid Red meat | J4: Forbid Pork | K4: Forbid Poultry | L4: Forbid Fish | M4: Forbid Eggs | N4: Forbid Dairy | O4: Forbid Gluten | P4: Also excluded (food # on Food Data) | Q4: Also excluded (names)
A5: Balanced | B5: USDA Acceptable Macronutrient Distribution Ranges; all foods allowed | C5: 0.1 | D5: 0.35 | E5: 0.45 | F5: 0.65 | G5: 0.2 | H5: 0.35 | I5: 0 | J5: 0 | K5: 0 | L5: 0 | M5: 0 | N5: 0 | O5: 0
A6: High-Protein | B6: For muscle gain: protein 25-35% of calories | C6: 0.25 | D6: 0.35 | E6: 0.4 | F6: 0.55 | G6: 0.2 | H6: 0.3 | I6: 0 | J6: 0 | K6: 0 | L6: 0 | M6: 0 | N6: 0 | O6: 0
A7: Low-Carb | B7: Moderate low-carb: carbs 20-35%, fat 35-50% (below the AMDR carb range) | C7: 0.2 | D7: 0.35 | E7: 0.2 | F7: 0.35 | G7: 0.35 | H7: 0.5 | I7: 0 | J7: 0 | K7: 0 | L7: 0 | M7: 0 | N7: 0 | O7: 0
A8: Vegetarian | B8: Lacto-ovo: no meat, poultry or fish | C8: 0.1 | D8: 0.35 | E8: 0.45 | F8: 0.65 | G8: 0.2 | H8: 0.35 | I8: 1 | J8: 1 | K8: 1 | L8: 1 | M8: 0 | N8: 0 | O8: 0
A9: Vegan | B9: No animal products | C9: 0.1 | D9: 0.35 | E9: 0.45 | F9: 0.65 | G9: 0.2 | H9: 0.35 | I9: 1 | J9: 1 | K9: 1 | L9: 1 | M9: 1 | N9: 1 | O9: 0
A10: Pescatarian | B10: Fish and seafood, no meat or poultry | C10: 0.1 | D10: 0.35 | E10: 0.45 | F10: 0.65 | G10: 0.2 | H10: 0.35 | I10: 1 | J10: 1 | K10: 1 | L10: 0 | M10: 0 | N10: 0 | O10: 0
A11: Gluten-Free | B11: No wheat, barley, rye or non-certified oats | C11: 0.1 | D11: 0.35 | E11: 0.45 | F11: 0.65 | G11: 0.2 | H11: 0.35 | I11: 0 | J11: 0 | K11: 0 | L11: 0 | M11: 0 | N11: 0 | O11: 1
A12: No Pork | B12: All foods except pork | C12: 0.1 | D12: 0.35 | E12: 0.45 | F12: 0.65 | G12: 0.2 | H12: 0.35 | I12: 0 | J12: 1 | K12: 0 | L12: 0 | M12: 0 | N12: 0 | O12: 0
A14: Low-Carb sets carbohydrate below the AMDR range (45–65%) on purpose; High-Protein sits at the top of the AMDR protein range.
A15: Diets change two things in the model: the macro rows of b_min/b_max, and the upper bounds u (a forbidden food gets u = 0).

Sheet Matrix Model
A1: Matrix Model — minimize cᵀx subject to G·x (≥ or ≤) b, 0 ≤ x ≤ u
A2: x = food amounts in 100 g units (column C below). A = nutrient matrix, M = meal matrix, G = every constraint row stacked. Solve with Data → Solver (see Planner).
B4: Selected diet | C4: =Planner!$C$36 -> Balanced
B7: Macro (% of kcal) | C7: min | D7: max
B8: Protein | C8: =INDEX(Diets!$C$5:$C$12,MATCH(Planner!$C$36,Diets!$A$5:$A$12,0)) -> 0.1 | D8: =INDEX(Diets!$D$5:$D$12,MATCH(Planner!$C$36,Diets!$A$5:$A$12,0)) -> 0.35
B9: Carbohydrate | C9: =INDEX(Diets!$E$5:$E$12,MATCH(Planner!$C$36,Diets!$A$5:$A$12,0)) -> 0.45 | D9: =INDEX(Diets!$F$5:$F$12,MATCH(Planner!$C$36,Diets!$A$5:$A$12,0)) -> 0.65
B10: Fat | C10: =INDEX(Diets!$G$5:$G$12,MATCH(Planner!$C$36,Diets!$A$5:$A$12,0)) -> 0.2 | D10: =INDEX(Diets!$H$5:$H$12,MATCH(Planner!$C$36,Diets!$A$5:$A$12,0)) -> 0.35
A12: FOOD PARAMETERS (one column per food)
