Workbook

Sheet Food Data
A1: Food Data — prices, edible yields, and nutrients per 100 g edible portion
A2: Prices: BLS Average Price Data, U.S. city average, September 2026. Nutrients: USDA National Nutrient Database for Standard Reference, Release 28 (SR28). See "Notes & Sources".
A3: Legend: blue = input data (edit freely) black = formula yellow = price still needed (BLS no longer publishes it) — enter a local price and the food joins the model.
A5: # | B5: Food | C5: Category | D5: BLS item (exact name) | E5: Price ($) | F5: Price unit | G5: Grams per price unit (as bought) | H5: Edible yield | I5: Edible grams per unit | J5: Cost per 100 g edible ($) | K5: Serving (g) | L5: Serving | M5: Cost per serving ($) | N5: Max servings / day | O5: Calories (kcal) | P5: Protein (g) | Q5: Carbohydrate (g) | R5: Fat (g) | S5: Fiber (g) | T5: Total sugars (g) | U5: Calcium (mg) | V5: Iron (mg) | W5: Potassium (mg) | X5: Sodium (mg) | Y5: Vitamin C (mg) | Z5: Protein per $ (g) | AA5: Calories per $ (kcal) | AB5: USDA NDB No. | AC5: USDA food description | AD5: USDA refuse | AE5: Notes
A6: 1 | B6: White rice (dry) | C6: Grains | D6: Rice, white, long grain, uncooked | E6: 1.118 | F6: per lb | G6: 453.6 | H6: 1 | I6: =G6*H6 -> 453.6 | J6: =IF(E6="","",E6/I6*100) -> 0.24647266 | K6: 46 | L6: 1/4 cup dry (~3/4 cup cooked) | M6: =IF(J6="","",J6*K6/100) -> 0.11337743 | N6: 4 | O6: 365 | P6: 7.13 | Q6: 79.95 | R6: 0.66 | S6: 1.3 | T6: 0.12 | U6: 28 | V6: 4.31 | W6: 115 | X6: 5 | Y6: 0 | Z6: =IF(J6="","",P6/J6) -> 28.928157 | AA6: =IF(J6="","",O6/J6) -> 1480.8945 | AB6: 20044 | AC6: Rice, white, long-grain, regular, raw, enriched | AD6: 0%
A7: 2 | B7: Spaghetti / macaroni (dry) | C7: Grains | D7: Spaghetti and macaroni | E7: 1.375 | F7: per lb | G7: 453.6 | H7: 1 | I7: =G7*H7 -> 453.6 | J7: =IF(E7="","",E7/I7*100) -> 0.30313051 | K7: 57 | L7: 2 oz dry | M7: =IF(J7="","",J7*K7/100) -> 0.17278439 | N7: 3 | O7: 371 | P7: 13.04 | Q7: 74.67 | R7: 1.51 | S7: 3.2 | T7: 2.67 | U7: 21 | V7: 3.3 | W7: 223 | X7: 6 | Y7: 0 | Z7: =IF(J7="","",P7/J7) -> 43.017775 | AA7: =IF(J7="","",O7/J7) -> 1223.8953 | AB7: 20120 | AC7: Pasta, dry, enriched | AD7: 0%
A8: 3 | B8: White bread | C8: Grains | D8: Bread, white, pan | E8: 1.83 | F8: per lb | G8: 453.6 | H8: 1 | I8: =G8*H8 -> 453.6 | J8: =IF(E8="","",E8/I8*100) -> 0.40343915 | K8: 29 | L8: 1 slice | M8: =IF(J8="","",J8*K8/100) -> 0.11699735 | N8: 6 | O8: 266 | P8: 8.85 | Q8: 49.42 | R8: 3.33 | S8: 2.7 | T8: 5.67 | U8: 144 | V8: 3.61 | W8: 126 | X8: 490 | Y8: 0 | Z8: =IF(J8="","",P8/J8) -> 21.936393 | AA8: =IF(J8="","",O8/J8) -> 659.33115 | AB8: 18069 | AC8: Bread, white, commercially prepared (includes soft bread crumbs) | AD8: 0%
A9: 4 | B9: All-purpose flour | C9: Grains | D9: Flour, white, all purpose | E9: 0.545 | F9: per lb | G9: 453.6 | H9: 1 | I9: =G9*H9 -> 453.6 | J9: =IF(E9="","",E9/I9*100) -> 0.12014991 | K9: 31 | L9: 1/4 cup | M9: =IF(J9="","",J9*K9/100) -> 0.037246473 | N9: 3 | O9: 364 | P9: 10.33 | Q9: 76.31 | R9: 0.98 | S9: 2.7 | T9: 0.27 | U9: 15 | V9: 4.64 | W9: 107 | X9: 2 | Y9: 0 | Z9: =IF(J9="","",P9/J9) -> 85.975927 | AA9: =IF(J9="","",O9/J9) -> 3029.5486 | AB9: 20081 | AC9: Wheat flour, white, all-purpose, enriched, bleached | AD9: 0% | AE9: Ingredient (pancakes, tortillas)
A10: 5 | B10: Dried pinto beans | C10: Legumes | D10: Beans, dried, any type, all sizes | E10: 1.669 | F10: per lb | G10: 453.6 | H10: 1 | I10: =G10*H10 -> 453.6 | J10: =IF(E10="","",E10/I10*100) -> 0.36794533 | K10: 48 | L10: 1/4 cup dry (~3/4 cup cooked) | M10: =IF(J10="","",J10*K10/100) -> 0.17661376 | N10: 4 | O10: 347 | P10: 21.42 | Q10: 62.55 | R10: 1.23 | S10: 15.5 | T10: 2.11 | U10: 113 | V10: 5.07 | W10: 1393 | X10: 12 | Y10: 6.3 | Z10: =IF(J10="","",P10/J10) -> 58.215171 | AA10: =IF(J10="","",O10/J10) -> 943.0749 | AB10: 16042 | AC10: Beans, pinto, mature seeds, raw | AD10: 0% | AE10: BLS item covers any dried bean; pinto used as the representative type
A11: 6 | B11: Ground beef (regular) | C11: Meat | D11: Ground beef, 100% beef | E11: 6.792 | F11: per lb | G11: 453.6 | H11: 1 | I11: =G11*H11 -> 453.6 | J11: =IF(E11="","",E11/I11*100) -> 1.4973545 | K11: 113 | L11: 4 oz raw | M11: =IF(J11="","",J11*K11/100) -> 1.6920106 | N11: 2 | O11: 254 | P11: 17.17 | Q11: 0 | R11: 20 | S11: 0 | T11: 0 | U11: 18 | V11: 1.94 | W11: 270 | X11: 66 | Y11: 0 | Z11: =IF(J11="","",P11/J11) -> 11.46689 | AA11: =IF(J11="","",O11/J11) -> 169.63251 | AB11: 23572 | AC11: Beef, ground, 80% lean meat / 20% fat, raw | AD11: 0% | AE11: Assumed 80/20 lean/fat; BLS does not state fat %
A12: 7 | B12: Ground beef (lean) | C12: Meat | D12: Ground beef, lean and extra lean | E12: 8.461 | F12: per lb | G12: 453.6 | H12: 1 | I12: =G12*H12 -> 453.6 | J12: =IF(E12="","",E12/I12*100) -> 1.8652998 | K12: 113 | L12: 4 oz raw | M12: =IF(J12="","",J12*K12/100) -> 2.1077888 | N12: 2 | O12: 176 | P12: 20 | Q12: 0 | R12: 10 | S12: 0 | T12: 0 | U12: 12 | V12: 2.24 | W12: 321 | X12: 66 | Y12: 0 | Z12: =IF(J12="","",P12/J12) -> 10.722137 | AA12: =IF(J12="","",O12/J12) -> 94.354804 | AB12: 23562 | AC12: Beef, ground, 90% lean meat / 10% fat, raw | AD12: 0% | AE12: Assumed 90/10 lean/fat
A13: 8 | B13: Sirloin steak | C13: Meat | D13: Steak, sirloin, USDA Choice, boneless | E13: 14.106 | F13: per lb | G13: 453.6 | H13: 0.97 | I13: =G13*H13 -> 439.992 | J13: =IF(E13="","",E13/I13*100) -> 3.2059674 | K13: 113 | L13: 4 oz raw | M13: =IF(J13="","",J13*K13/100) -> 3.6227431 | N13: 2 | O13: 214 | P13: 19.92 | Q13: 0 | R13: 14.28 | S13: 0 | T13: 0 | U13: 25 | V13: 1.46 | W13: 309 | X13: 51 | Y13: 0 | Z13: =IF(J13="","",P13/J13) -> 6.2134132 | AA13: =IF(J13="","",O13/J13) -> 66.750523 | AB13: 13931 | AC13: Beef, top sirloin, steak, separable lean and fat, trimmed to 1/8" fat, choice, raw | AD13: 3% Bone and connective tissue
A14: 9 | B14: Bacon | C14: Meat | D14: Bacon, sliced | E14: 6.756 | F14: per lb | G14: 453.6 | H14: 1 | I14: =G14*H14 -> 453.6 | J14: =IF(E14="","",E14/I14*100) -> 1.489418 | K14: 28 | L14: 1 slice raw | M14: =IF(J14="","",J14*K14/100) -> 0.41703704 | N14: 3 | O14: 417 | P14: 12.62 | Q14: 1.28 | R14: 39.69 | S14: 0 | T14: 1 | U14: 5 | V14: 0.41 | W14: 198 | X14: 662 | Y14: 0 | Z14: =IF(J14="","",P14/J14) -> 8.4731083 | AA14: =IF(J14="","",O14/J14) -> 279.97513 | AB14: 10123 | AC14: Pork, cured, bacon, unprepared | AD14: 0%
A15: 10 | B15: Pork chops (boneless) | C15: Meat | D15: Chops, boneless | E15: 4.55 | F15: per lb | G15: 453.6 | H15: 1 | I15: =G15*H15 -> 453.6 | J15: =IF(E15="","",E15/I15*100) -> 1.0030864 | K15: 113 | L15: 4 oz raw | M15: =IF(J15="","",J15*K15/100) -> 1.1334877 | N15: 2 | O15: 201 | P15: 21.14 | Q15: 0 | R15: 12.96 | S15: 0 | T15: 0 | U15: 9 | V15: 0.48 | W15: 345 | X15: 82 | Y15: 0 | Z15: =IF(J15="","",P15/J15) -> 21.074954 | AA15: =IF(J15="","",O15/J15) -> 200.38154 | AB15: 10164 | AC15: Pork, fresh, loin, center loin (chops), boneless, separable lean and fat, raw | AD15: 0%
A16: 11 | B16: Ham (boneless) | C16: Meat | D16: Ham, boneless, excluding canned | E16: 5.45 | F16: per lb | G16: 453.6 | H16: 1 | I16: =G16*H16 -> 453.6 | J16: =IF(E16="","",E16/I16*100) -> 1.2014991 | K16: 56 | L16: 2 slices | M16: =IF(J16="","",J16*K16/100) -> 0.67283951 | N16: 2 | O16: 163 | P16: 16.6 | Q16: 3.83 | R16: 8.6 | S16: 1.3 | T16: 0 | U16: 24 | V16: 1.02 | W16: 287 | X16: 1143 | Y16: 4 | Z16: =IF(J16="","",P16/J16) -> 13.816073 | AA16: =IF(J16="","",O16/J16) -> 135.66385 | AB16: 07029 | AC16: Ham, sliced, regular (approximately 11% fat) | AD16: 0% | AE16: Nutrients for sliced regular ham (~11% fat)
A17: 12 | B17: Whole chicken | C17: Poultry | D17: Chicken, fresh, whole | E17: 2.064 | F17: per lb | G17: 453.6 | H17: 0.68 | I17: =G17*H17 -> 308.448 | J17: =IF(E17="","",E17/I17*100) -> 0.66915655 | K17: 113 | L17: 4 oz raw meat & skin | M17: =IF(J17="","",J17*K17/100) -> 0.7561469 | N17: 2 | O17: 215 | P17: 18.6 | Q17: 0 | R17: 15.06 | S17: 0 | T17: 0 | U17: 11 | V17: 0.9 | W17: 189 | X17: 70 | Y17: 1.6 | Z17: =IF(J17="","",P17/J17) -> 27.796186 | AA17: =IF(J17="","",O17/J17) -> 321.3 | AB17: 05006 | AC17: Chicken, broilers or fryers, meat and skin, raw | AD17: 32% Bone | AE17: Price includes bone; edible yield applied
A18: 13 | B18: Chicken breast (boneless) | C18: Poultry | D18: Chicken breast, boneless | E18: 4.203 | F18: per lb | G18: 453.6 | H18: 1 | I18: =G18*H18 -> 453.6 | J18: =IF(E18="","",E18/I18*100) -> 0.9265873 | K18: 113 | L18: 4 oz raw | M18: =IF(J18="","",J18*K18/100) -> 1.0470437 | N18: 3 | O18: 120 | P18: 22.5 | Q18: 0 | R18: 2.62 | S18: 0 | T18: 0 | U18: 5 | V18: 0.37 | W18: 334 | X18: 45 | Y18: 0 | Z18: =IF(J18="","",P18/J18) -> 24.282655 | AA18: =IF(J18="","",O18/J18) -> 129.50749 | AB18: 05062 | AC18: Chicken, broiler or fryers, breast, skinless, boneless, meat only, raw | AD18: 0%
A19: 14 | B19: Chicken legs (bone-in) | C19: Poultry | D19: Chicken legs, bone-in | E19: 1.739 | F19: per lb | G19: 453.6 | H19: 0.73 | I19: =G19*H19 -> 331.128 | J19: =IF(E19="","",E19/I19*100) -> 0.52517455 | K19: 113 | L19: 4 oz raw meat & skin | M19: =IF(J19="","",J19*K19/100) -> 0.59344725 | N19: 2 | O19: 214 | P19: 16.37 | Q19: 0.17 | R19: 15.95 | S19: 0 | T19: 0 | U19: 9 | V19: 0.69 | W19: 203 | X19: 84 | Y19: 0.2 | Z19: =IF(J19="","",P19/J19) -> 31.170589 | AA19: =IF(J19="","",O19/J19) -> 407.48357 | AB19: 05075 | AC19: Chicken, broilers or fryers, leg, meat and skin, raw | AD19: 27% Bone | AE19: Price includes bone; edible yield applied
A20: 15 | B20: Eggs (large) | C20: Eggs & Dairy | D20: Eggs, grade A, large | E20: 2.272 | F20: per dozen | G20: =12*50/0.88 -> 681.81818 | H20: 0.88 | I20: =G20*H20 -> 600 | J20: =IF(E20="","",E20/I20*100) -> 0.37866667 | K20: 50 | L20: 1 large egg | M20: =IF(J20="","",J20*K20/100) -> 0.18933333 | N20: 4 | O20: 143 | P20: 12.56 | Q20: 0.72 | R20: 9.51 | S20: 0 | T20: 0.37 | U20: 56 | V20: 1.75 | W20: 138 | X20: 142 | Y20: 0 | Z20: =IF(J20="","",P20/J20) -> 33.169014 | AA20: =IF(J20="","",O20/J20) -> 377.64085 | AB20: 01123 | AC20: Egg, whole, raw, fresh | AD20: 12% Shell | AE20: Dozen = 12 x 50 g edible egg; shell is 12% of purchase weight
A21: 16 | B21: Whole milk | C21: Eggs & Dairy | D21: Milk, fresh, whole, fortified | E21: 4.106 | F21: per gallon | G21: =16*244 -> 3904 | H21: 1 | I21: =G21*H21 -> 3904 | J21: =IF(E21="","",E21/I21*100) -> 0.10517418 | K21: 244 | L21: 1 cup | M21: =IF(J21="","",J21*K21/100) -> 0.256625 | N21: 4 | O21: 61 | P21: 3.15 | Q21: 4.8 | R21: 3.25 | S21: 0 | T21: 5.05 | U21: 113 | V21: 0.03 | W21: 132 | X21: 43 | Y21: 0 | Z21: =IF(J21="","",P21/J21) -> 29.950317 | AA21: =IF(J21="","",O21/J21) -> 579.99026 | AB21: 01077 | AC21: Milk, whole, 3.25% milkfat, with added vitamin D | AD21: 0% | AE21: Gallon = 16 cups x 244 g
A22: 17 | B22: Cheddar cheese | C22: Eggs & Dairy | D22: Cheddar cheese, natural | E22: 6.133 | F22: per lb | G22: 453.6 | H22: 1 | I22: =G22*H22 -> 453.6 | J22: =IF(E22="","",E22/I22*100) -> 1.3520723 | K22: 28 | L22: 1 oz | M22: =IF(J22="","",J22*K22/100) -> 0.37858025 | N22: 3 | O22: 404 | P22: 22.87 | Q22: 3.09 | R22: 33.31 | S22: 0 | T22: 0.48 | U22: 710 | V22: 0.14 | W22: 76 | X22: 653 | Y22: 0 | Z22: =IF(J22="","",P22/J22) -> 16.914776 | AA22: =IF(J22="","",O22/J22) -> 298.80059 | AB22: 01009 | AC22: Cheese, cheddar | AD22: 0%
A23: 18 | B23: American cheese | C23: Eggs & Dairy | D23: American processed cheese | E23: 4.737 | F23: per lb | G23: 453.6 | H23: 1 | I23: =G23*H23 -> 453.6 | J23: =IF(E23="","",E23/I23*100) -> 1.0443122 | K23: 28 | L23: 1 slice | M23: =IF(J23="","",J23*K23/100) -> 0.29240741 | N23: 3 | O23: 366 | P23: 18.13 | Q23: 4.78 | R23: 30.71 | S23: 0 | T23: 2.26 | U23: 1045 | V23: 0.63 | W23: 132 | X23: 1671 | Y23: 0 | Z23: =IF(J23="","",P23/J23) -> 17.360709 | AA23: =IF(J23="","",O23/J23) -> 350.46992 | AB23: 01042 | AC23: Cheese, pasteurized process, American, fortified with vitamin D | AD23: 0%
A24: 19 | B24: Vanilla ice cream | C24: Snacks & Sweets | D24: Ice cream, prepackaged, bulk, regular | E24: 5.931 | F24: per 1/2 gallon | G24: =8*132 -> 1056 | H24: 1 | I24: =G24*H24 -> 1056 | J24: =IF(E24="","",E24/I24*100) -> 0.56164773 | K24: 66 | L24: 1/2 cup | M24: =IF(J24="","",J24*K24/100) -> 0.3706875 | N24: 2 | O24: 207 | P24: 3.5 | Q24: 23.6 | R24: 11 | S24: 0.7 | T24: 21.22 | U24: 128 | V24: 0.09 | W24: 199 | X24: 80 | Y24: 0.6 | Z24: =IF(J24="","",P24/J24) -> 6.2316641 | AA24: =IF(J24="","",O24/J24) -> 368.55842 | AB24: 19095 | AC24: Ice creams, vanilla | AD24: 0% | AE24: 1/2 gallon = 8 cups x 132 g
A25: 20 | B25: Bananas | C25: Fruit | D25: Bananas | E25: 0.656 | F25: per lb | G25: 453.6 | H25: 0.64 | I25: =G25*H25 -> 290.304 | J25: =IF(E25="","",E25/I25*100) -> 0.22597002 | K25: 118 | L25: 1 medium | M25: =IF(J25="","",J25*K25/100) -> 0.26664462 | N25: 3 | O25: 89 | P25: 1.09 | Q25: 22.84 | R25: 0.33 | S25: 2.6 | T25: 12.23 | U25: 5 | V25: 0.26 | W25: 358 | X25: 1 | Y25: 8.7 | Z25: =IF(J25="","",P25/J25) -> 4.8236488 | AA25: =IF(J25="","",O25/J25) -> 393.85756 | AB25: 09040 | AC25: Bananas, raw | AD25: 36% Skin | AE25: Price includes peel; edible yield applied
A26: 21 | B26: Navel oranges | C26: Fruit | D26: Oranges, Navel | E26: 1.723 | F26: per lb | G26: 453.6 | H26: 0.68 | I26: =G26*H26 -> 308.448 | J26: =IF(E26="","",E26/I26*100) -> 0.55860307 | K26: 140 | L26: 1 orange | M26: =IF(J26="","",J26*K26/100) -> 0.7820443 | N26: 3 | O26: 49 | P26: 0.91 | Q26: 12.54 | R26: 0.15 | S26: 2.2 | T26: 8.5 | U26: 43 | V26: 0.13 | W26: 166 | X26: 1 | Y26: 59.1 | Z26: =IF(J26="","",P26/J26) -> 1.6290637 | AA26: =IF(J26="","",O26/J26) -> 87.718816 | AB26: 09202 | AC26: Oranges, raw, navels | AD26: 32% Peel and navel | AE26: Price includes peel; edible yield applied
A27: 22 | B27: Strawberries | C27: Fruit | D27: Strawberries, dry pint | E27: 2.84 | F27: per 12 oz | G27: 340.2 | H27: 0.94 | I27: =G27*H27 -> 319.788 | J27: =IF(E27="","",E27/I27*100) -> 0.88808836 | K27: 152 | L27: 1 cup halves | M27: =IF(J27="","",J27*K27/100) -> 1.3498943 | N27: 2 | O27: 32 | P27: 0.67 | Q27: 7.68 | R27: 0.3 | S27: 2 | T27: 4.89 | U27: 16 | V27: 0.41 | W27: 153 | X27: 1 | Y27: 58.8 | Z27: =IF(J27="","",P27/J27) -> 0.75442944 | AA27: =IF(J27="","",O27/J27) -> 36.032451 | AB27: 09316 | AC27: Strawberries, raw | AD27: 6% Caps and stems
A28: 23 | B28: White potatoes | C28: Vegetables | D28: Potatoes, white | E28: 0.989 | F28: per lb | G28: 453.6 | H28: 0.75 | I28: =G28*H28 -> 340.2 | J28: =IF(E28="","",E28/I28*100) -> 0.29071135 | K28: 150 | L28: 1 cup diced | M28: =IF(J28="","",J28*K28/100) -> 0.43606702 | N28: 3 | O28: 77 | P28: 2.05 | Q28: 17.49 | R28: 0.09 | S28: 2.1 | T28: 0.82 | U28: 12 | V28: 0.81 | W28: 425 | X28: 6 | Y28: 19.7 | Z28: =IF(J28="","",P28/J28) -> 7.0516684 | AA28: =IF(J28="","",O28/J28) -> 264.86754 | AB28: 11352 | AC28: Potatoes, flesh and skin, raw | AD28: 25% Parings and trimmings | AE28: USDA refuse assumes peeled; eating the skin raises the yield
A29: 24 | B29: Iceberg lettuce | C29: Vegetables | D29: Lettuce, iceberg | E29: 1.636 | F29: per lb | G29: 453.6 | H29: 0.95 | I29: =G29*H29 -> 430.92 | J29: =IF(E29="","",E29/I29*100) -> 0.37965284 | K29: 72 | L29: 1 cup shredded | M29: =IF(J29="","",J29*K29/100) -> 0.27335004 | N29: 4 | O29: 14 | P29: 0.9 | Q29: 2.97 | R29: 0.14 | S29: 1.2 | T29: 1.97 | U29: 18 | V29: 0.41 | W29: 141 | X29: 10 | Y29: 2.8 | Z29: =IF(J29="","",P29/J29) -> 2.3705868 | AA29: =IF(J29="","",O29/J29) -> 36.875795 | AB29: 11252 | AC29: Lettuce, iceberg (includes crisphead types), raw | AD29: 5% Core
A30: 25 | B30: Romaine lettuce | C30: Vegetables | D30: Lettuce, romaine | E30: 3.312 | F30: per lb | G30: 453.6 | H30: 0.94 | I30: =G30*H30 -> 426.384 | J30: =IF(E30="","",E30/I30*100) -> 0.77676461 | K30: 47 | L30: 1 cup shredded | M30: =IF(J30="","",J30*K30/100) -> 0.36507937 | N30: 4 | O30: 17 | P30: 1.23 | Q30: 3.29 | R30: 0.3 | S30: 2.1 | T30: 1.19 | U30: 33 | V30: 0.97 | W30: 247 | X30: 8 | Y30: 4 | Z30: =IF(J30="","",P30/J30) -> 1.5834913 | AA30: =IF(J30="","",O30/J30) -> 21.885652 | AB30: 11251 | AC30: Lettuce, cos or romaine, raw | AD30: 6% Core
A31: 26 | B31: Tomatoes | C31: Vegetables | D31: Tomatoes, field grown | E31: 1.992 | F31: per lb | G31: 453.6 | H31: 0.91 | I31: =G31*H31 -> 412.776 | J31: =IF(E31="","",E31/I31*100) -> 0.4825862 | K31: 180 | L31: 1 cup chopped | M31: =IF(J31="","",J31*K31/100) -> 0.86865515 | N31: 2 | O31: 18 | P31: 0.88 | Q31: 3.89 | R31: 0.2 | S31: 1.2 | T31: 2.63 | U31: 10 | V31: 0.27 | W31: 237 | X31: 5 | Y31: 13.7 | Z31: =IF(J31="","",P31/J31) -> 1.8235084 | AA31: =IF(J31="","",O31/J31) -> 37.299036 | AB31: 11529 | AC31: Tomatoes, red, ripe, raw, year round average | AD31: 9% Core and stem ends
A32: 27 | B32: White sugar | C32: Snacks & Sweets | D32: Sugar, white, all sizes | E32: 1.019 | F32: per lb | G32: 453.6 | H32: 1 | I32: =G32*H32 -> 453.6 | J32: =IF(E32="","",E32/I32*100) -> 0.22464727 | K32: 4.2 | L32: 1 tsp | M32: =IF(J32="","",J32*K32/100) -> 0.0094351852 | N32: 6 | O32: 387 | P32: 0 | Q32: 99.98 | R32: 0 | S32: 0 | T32: 99.8 | U32: 1 | V32: 0.05 | W32: 2 | X32: 1 | Y32: 0 | Z32: =IF(J32="","",P32/J32) -> 0 | AA32: =IF(J32="","",O32/J32) -> 1722.7007 | AB32: 19335 | AC32: Sugars, granulated | AD32: 0%
A33: 28 | B33: Chocolate chip cookies | C33: Snacks & Sweets | D33: Cookies, chocolate chip | E33: 5.152 | F33: per lb | G33: 453.6 | H33: 1 | I33: =G33*H33 -> 453.6 | J33: =IF(E33="","",E33/I33*100) -> 1.1358025 | K33: 25.8 | L33: 2 cookies | M33: =IF(J33="","",J33*K33/100) -> 0.29303704 | N33: 2 | O33: 492 | P33: 5.1 | Q33: 65.36 | R33: 24.72 | S33: 2 | T33: 32.9 | U33: 21 | V33: 5.58 | W33: 171 | X33: 311 | Y33: 0 | Z33: =IF(J33="","",P33/J33) -> 4.4902174 | AA33: =IF(J33="","",O33/J33) -> 433.17391 | AB33: 18159 | AC33: Cookies, chocolate chip, commercially prepared, regular, higher fat, enriched | AD33: 0%
A34: 29 | B34: Potato chips | C34: Snacks & Sweets | D34: Potato chips | E34: 6.668 | F34: per 16 oz | G34: 453.6 | H34: 1 | I34: =G34*H34 -> 453.6 | J34: =IF(E34="","",E34/I34*100) -> 1.4700176 | K34: 28 | L34: 1 oz | M34: =IF(J34="","",J34*K34/100) -> 0.41160494 | N34: 2 | O34: 532 | P34: 6.39 | Q34: 53.83 | R34: 33.98 | S34: 3.1 | T34: 0.33 | U34: 21 | V34: 1.28 | W34: 1196 | X34: 527 | Y34: 21.6 | Z34: =IF(J34="","",P34/J34) -> 4.3468866 | AA34: =IF(J34="","",O34/J34) -> 361.90042 | AB34: 19411 | AC34: Snacks, potato chips, plain, salted | AD34: 0%
A35: 30 | B35: Peanut butter | C35: Legumes | D35: (BLS series discontinued Dec 2017) | F35: per lb | G35: 453.6 | H35: 1 | I35: =G35*H35 -> 453.6 | J35: =IF(E35="","",E35/I35*100) | K35: 32 | L35: 2 tbsp | M35: =IF(J35="","",J35*K35/100) | N35: 2 | O35: 598 | P35: 22.21 | Q35: 22.31 | R35: 51.36 | S35: 5 | T35: 10.49 | U35: 49 | V35: 1.74 | W35: 558 | X35: 426 | Y35: 0 | Z35: =IF(J35="","",P35/J35) | AA35: =IF(J35="","",O35/J35) | AB35: 16098 | AC35: Peanut butter, smooth style, with salt | AD35: 0% | AE35: Enter a local price
A36: 31 | B36: Rolled oats (dry) | C36: Grains | D36: (not priced by BLS) | F36: per lb | G36: 453.6 | H36: 1 | I36: =G36*H36 -> 453.6 | J36: =IF(E36="","",E36/I36*100) | K36: 40.5 | L36: 1/2 cup dry | M36: =IF(J36="","",J36*K36/100) | N36: 3 | O36: 379 | P36: 13.15 | Q36: 67.7 | R36: 6.52 | S36: 10.1 | T36: 0.99 | U36: 52 | V36: 4.25 | W36: 362 | X36: 6 | Y36: 0 | Z36: =IF(J36="","",P36/J36) | AA36: =IF(J36="","",O36/J36) | AB36: 08120 | AC36: Cereals, oats, regular and quick, not fortified, dry | AD36: 0% | AE36: Enter a local price
A37: 32 | B37: Broccoli | C37: Vegetables | D37: (BLS series discontinued Mar 2020) | F37: per lb | G37: 453.6 | H37: 0.61 | I37: =G37*H37 -> 276.696 | J37: =IF(E37="","",E37/I37*100) | K37: 91 | L37: 1 cup chopped | M37: =IF(J37="","",J37*K37/100) | N37: 3 | O37: 34 | P37: 2.82 | Q37: 6.64 | R37: 0.37 | S37: 2.6 | T37: 1.7 | U37: 47 | V37: 0.73 | W37: 316 | X37: 33 | Y37: 89.2 | Z37: =IF(J37="","",P37/J37) | AA37: =IF(J37="","",O37/J37) | AB37: 11090 | AC37: Broccoli, raw | AD37: 39% Leaves and tough stalks with trimmings | AE37: Enter a local price
A38: 33 | B38: Carrots | C38: Vegetables | D38: (BLS series discontinued Mar 2014) | F38: per lb | G38: 453.6 | H38: 0.89 | I38: =G38*H38 -> 403.704 | J38: =IF(E38="","",E38/I38*100) | K38: 128 | L38: 1 cup chopped | M38: =IF(J38="","",J38*K38/100) | N38: 2 | O38: 41 | P38: 0.93 | Q38: 9.58 | R38: 0.24 | S38: 2.8 | T38: 4.74 | U38: 33 | V38: 0.3 | W38: 320 | X38: 69 | Y38: 5.9 | Z38: =IF(J38="","",P38/J38) | AA38: =IF(J38="","",O38/J38) | AB38: 11124 | AC38: Carrots, raw | AD38: 11% Crown, tops and scrapings | AE38: Enter a local price
A39: 34 | B39: Apples | C39: Fruit | D39: (BLS series discontinued Oct 2017) | F39: per lb | G39: 453.6 | H39: 0.9 | I39: =G39*H39 -> 408.24 | J39: =IF(E39="","",E39/I39*100) | K39: 125 | L39: 1 cup chopped | M39: =IF(J39="","",J39*K39/100) | N39: 3 | O39: 52 | P39: 0.26 | Q39: 13.81 | R39: 0.17 | S39: 2.4 | T39: 10.39 | U39: 6 | V39: 0.12 | W39: 107 | X39: 1 | Y39: 4.6 | Z39: =IF(J39="","",P39/J39) | AA39: =IF(J39="","",O39/J39) | AB39: 09003 | AC39: Apples, raw, with skin | AD39: 10% Core and stem | AE39: Enter a local price
A40: 35 | B40: Canned light tuna (drained) | C40: Fish | D40: (not priced by BLS) | F40: per lb drained | G40: 453.6 | H40: 1 | I40: =G40*H40 -> 453.6 | J40: =IF(E40="","",E40/I40*100) | K40: 85 | L40: 3 oz drained | M40: =IF(J40="","",J40*K40/100) | N40: 2 | O40: 86 | P40: 19.44 | Q40: 0 | R40: 0.96 | S40: 0 | T40: 0 | U40: 17 | V40: 1.63 | W40: 179 | X40: 247 | Y40: 0 | Z40: =IF(J40="","",P40/J40) | AA40: =IF(J40="","",O40/J40) | AB40: 15121 | AC40: Fish, tuna, light, canned in water, drained solids | AD40: 0% | AE40: Enter a local price per lb of drained tuna
A41: 36 | B41: Butter (salted) | C41: Eggs & Dairy | D41: (BLS series discontinued Apr 2012) | F41: per lb | G41: 453.6 | H41: 1 | I41: =G41*H41 -> 453.6 | J41: =IF(E41="","",E41/I41*100) | K41: 14.2 | L41: 1 tbsp | M41: =IF(J41="","",J41*K41/100) | N41: 2 | O41: 717 | P41: 0.85 | Q41: 0.06 | R41: 81.11 | S41: 0 | T41: 0.06 | U41: 24 | V41: 0.02 | W41: 24 | X41: 643 | Y41: 0 | Z41: =IF(J41="","",P41/J41) | AA41: =IF(J41="","",O41/J41) | AB41: 01001 | AC41: Butter, salted | AD41: 0% | AE41: Enter a local price

Sheet Matrix Model
A1: Diet optimization as a linear program in matrix form
A2: minimize cᵀx subject to b_min ≤ A·x ≤ b_max, 0 ≤ x ≤ u (x_j = amount of food j per day, in 100 g units)
A3: A (11 nutrients × 36 foods) is pulled from Food Data. A·x and cᵀx are matrix products (MMULT). Change the blue targets, then re-solve (website optimizer or Excel Solver — see Notes & Sources).
A5: 1. TARGETS (inputs — paste from the FeasaBULL calculator)
A6: Input | B6: Value / min | C6: Max | D6: Basis
A7: Calorie target (kcal/day) | B7: 2600 | D7: Estimated Energy Requirement from the calculator
A8: Calorie tolerance (±) | B8: 0.05 | D8: Allowed band around the calorie target
A9: Protein (% of calories) | B9: 0.1 | C9: 0.35 | D9: AMDR, adults
A10: Carbohydrate (% of calories) | B10: 0.45 | C10: 0.65 | D10: AMDR, adults
A11: Fat (% of calories) | B11: 0.2 | C11: 0.35 | D11: AMDR, adults
A12: Fiber (g) | B12: 38 | D12: AI, men 19–50 (women: 25)
A13: Calcium (mg) | B13: 1000 | D13: RDA, adults 19–50
A14: Iron (mg) | B14: 8 | D14: RDA, men 19+ (women 19–50: 18)
A15: Potassium (mg) | B15: 3400 | D15: AI, men 19+ (women: 2,600)
A16: Vitamin C (mg) | B16: 90 | D16: RDA, men (women: 75)
A17: Sodium (mg) | C17: 2300 | D17: Chronic Disease Risk Reduction intake (upper)
A18: Total sugars (g) | D18: Optional maximum — leave blank for none
A19: Example person: male, 19–30, active, maintain weight. Replace these with the calculator output for each user.
A21: 2. CONSTRAINT SYSTEM b_min ≤ A·x ≤ b_max (A = nutrient matrix: rows = nutrients, columns = foods, per 100 g edible)
A22: i | B22: Nutrient | C22: Unit | D22: b_min | E22: b_max | F22: A·x* (optimized) | G22: Status | H22: A·x (typical day) | I22: Typical-day status | K22: ='Food Data'!B6 -> White rice (dry) | L22: ='Food Data'!B7 -> Spaghetti / macaroni (dry) | M22: ='Food Data'!B8 -> White bread | N22: ='Food Data'!B9 -> All-purpose flour | O22: ='Food Data'!B10 -> Dried pinto beans | P22: ='Food Data'!B11 -> Ground beef (regular) | Q22: ='Food Data'!B12 -> Ground beef (lean) | R22: ='Food Data'!B13 -> Sirloin steak | S22: ='Food Data'!B14 -> Bacon | T22: ='Food Data'!B15 -> Pork chops (boneless) | U22: ='Food Data'!B16 -> Ham (boneless) | V22: ='Food Data'!B17 -> Whole chicken | W22: ='Food Data'!B18 -> Chicken breast (boneless) | X22: ='Food Data'!B19 -> Chicken legs (bone-in) | Y22: ='Food Data'!B20 -> Eggs (large) | Z22: ='Food Data'!B21 -> Whole milk | AA22: ='Food Data'!B22 -> Cheddar cheese | AB22: ='Food Data'!B23 -> American cheese | AC22: ='Food Data'!B24 -> Vanilla ice cream | AD22: ='Food Data'!B25 -> Bananas | AE22: ='Food Data'!B26 -> Navel oranges | AF22: ='Food Data'!B27 -> Strawberries | AG22: ='Food Data'!B28 -> White potatoes | AH22: ='Food Data'!B29 -> Iceberg lettuce | AI22: ='Food Data'!B30 -> Romaine lettuce | AJ22: ='Food Data'!B31 -> Tomatoes | AK22: ='Food Data'!B32 -> White sugar | AL22: ='Food Data'!B33 -> Chocolate chip cookies | AM22: ='Food Data'!B34 -> Potato chips | AN22: ='Food Data'!B35 -> Peanut butter | AO22: ='Food Data'!B36 -> Rolled oats (dry) | AP22: ='Food Data'!B37 -> Broccoli | AQ22: ='Food Data'!B38 -> Carrots | AR22: ='Food Data'!B39 -> Apples | AS22: ='Food Data'!B40 -> Canned light tuna (drained) | AT22: ='Food Data'!B41 -> Butter (salted)
A23: 1 | B23: Calories | C23: kcal | D23: =$B$7*(1-$B$8) -> 2470 | E23: =$B$7*(1+$B$8) -> 2730 | F23: {=MMULT(K23:AT33,C40:C75)} -> 2469.9997 | G23: =IF(F23<D23-0.01,"BELOW MIN",IF(F23>E23+0.01,"ABOVE MAX",IF(OR(ABS(F23-D23)<0.01,ABS(F23-E23)<0.01),"binding","ok"))) -> binding | H23: {=MMULT(K23:AT33,I40:I75)} -> 1714.216 | I23: =IF(H23<D23-0.01,"BELOW MIN",IF(H23>E23+0.01,"ABOVE MAX",IF(OR(ABS(H23-D23)<0.01,ABS(H23-E23)<0.01),"binding","ok"))) -> BELOW MIN | K23: ='Food Data'!O6 -> 365 | L23: ='Food Data'!O7 -> 371 | M23: ='Food Data'!O8 -> 266 | N23: ='Food Data'!O9 -> 364 | O23: ='Food Data'!O10 -> 347 | P23: ='Food Data'!O11 -> 254 | Q23: ='Food Data'!O12 -> 176 | R23: ='Food Data'!O13 -> 214 | S23: ='Food Data'!O14 -> 417 | T23: ='Food Data'!O15 -> 201 | U23: ='Food Data'!O16 -> 163 | V23: ='Food Data'!O17 -> 215 | W23: ='Food Data'!O18 -> 120 | X23: ='Food Data'!O19 -> 214 | Y23: ='Food Data'!O20 -> 143 | Z23: ='Food Data'!O21 -> 61 | AA23: ='Food Data'!O22 -> 404 | AB23: ='Food Data'!O23 -> 366 | AC23: ='Food Data'!O24 -> 207 | AD23: ='Food Data'!O25 -> 89 | AE23: ='Food Data'!O26 -> 49 | AF23: ='Food Data'!O27 -> 32 | AG23: ='Food Data'!O28 -> 77 | AH23: ='Food Data'!O29 -> 14 | AI23: ='Food Data'!O30 -> 17 | AJ23: ='Food Data'!O31 -> 18 | AK23: ='Food Data'!O32 -> 387 | AL23: ='Food Data'!O33 -> 492 | AM23: ='Food Data'!O34 -> 532 | AN23: ='Food Data'!O35 -> 598 | AO23: ='Food Data'!O36 -> 379 | AP23: ='Food Data'!O37 -> 34 | AQ23: ='Food Data'!O38 -> 41 | AR23: ='Food Data'!O39 -> 52 | AS23: ='Food Data'!O40 -> 86 | AT23: ='Food Data'!O41 -> 717
A24: 2 | B24: Protein | C24: g | D24: =$B$7*$B$9/4 -> 65 | E24: =$B$7*$C$9/4 -> 227.5 | F24: 117.64682 | G24: =IF(F24<D24-0.01,"BELOW MIN",IF(F24>E24+0.01,"ABOVE MAX",IF(OR(ABS(F24-D24)<0.01,ABS(F24-E24)<0.01),"binding","ok"))) -> ok | H24: 87.6733 | I24: =IF(H24<D24-0.01,"BELOW MIN",IF(H24>E24+0.01,"ABOVE MAX",IF(OR(ABS(H24-D24)<0.01,ABS(H24-E24)<0.01),"binding","ok"))) -> ok | K24: ='Food Data'!P6 -> 7.13 | L24: ='Food Data'!P7 -> 13.04 | M24: ='Food Data'!P8 -> 8.85 | N24: ='Food Data'!P9 -> 10.33 | O24: ='Food Data'!P10 -> 21.42 | P24: ='Food Data'!P11 -> 17.17 | Q24: ='Food Data'!P12 -> 20 | R24: ='Food Data'!P13 -> 19.92 | S24: ='Food Data'!P14 -> 12.62 | T24: ='Food Data'!P15 -> 21.14 | U24: ='Food Data'!P16 -> 16.6 | V24: ='Food Data'!P17 -> 18.6 | W24: ='Food Data'!P18 -> 22.5 | X24: ='Food Data'!P19 -> 16.37 | Y24: ='Food Data'!P20 -> 12.56 | Z24: ='Food Data'!P21 -> 3.15 | AA24: ='Food Data'!P22 -> 22.87 | AB24: ='Food Data'!P23 -> 18.13 | AC24: ='Food Data'!P24 -> 3.5 | AD24: ='Food Data'!P25 -> 1.09 | AE24: ='Food Data'!P26 -> 0.91 | AF24: ='Food Data'!P27 -> 0.67 | AG24: ='Food Data'!P28 -> 2.05 | AH24: ='Food Data'!P29 -> 0.9 | AI24: ='Food Data'!P30 -> 1.23 | AJ24: ='Food Data'!P31 -> 0.88 | AK24: ='Food Data'!P32 -> 0 | AL24: ='Food Data'!P33 -> 5.1 | AM24: ='Food Data'!P34 -> 6.39 | AN24: ='Food Data'!P35 -> 22.21 | AO24: ='Food Data'!P36 -> 13.15 | AP24: ='Food Data'!P37 -> 2.82 | AQ24: ='Food Data'!P38 -> 0.93 | AR24: ='Food Data'!P39 -> 0.26 | AS24: ='Food Data'!P40 -> 19.44 | AT24: ='Food Data'!P41 -> 0.85
A25: 3 | B25: Carbohydrate | C25: g | D25: =$B$7*$B$10/4 -> 292.5 | E25: =$B$7*$C$10/4 -> 422.5 | F25: 365.27715 | G25: =IF(F25<D25-0.01,"BELOW MIN",IF(F25>E25+0.01,"ABOVE MAX",IF(OR(ABS(F25-D25)<0.01,ABS(F25-E25)<0.01),"binding","ok"))) -> ok | H25: 180.51388 | I25: =IF(H25<D25-0.01,"BELOW MIN",IF(H25>E25+0.01,"ABOVE MAX",IF(OR(ABS(H25-D25)<0.01,ABS(H25-E25)<0.01),"binding","ok"))) -> BELOW MIN | K25: ='Food Data'!Q6 -> 79.95 | L25: ='Food Data'!Q7 -> 74.67 | M25: ='Food Data'!Q8 -> 49.42 | N25: ='Food Data'!Q9 -> 76.31 | O25: ='Food Data'!Q10 -> 62.55 | P25: ='Food Data'!Q11 -> 0 | Q25: ='Food Data'!Q12 -> 0 | R25: ='Food Data'!Q13 -> 0 | S25: ='Food Data'!Q14 -> 1.28 | T25: ='Food Data'!Q15 -> 0 | U25: ='Food Data'!Q16 -> 3.83 | V25: ='Food Data'!Q17 -> 0 | W25: ='Food Data'!Q18 -> 0 | X25: ='Food Data'!Q19 -> 0.17 | Y25: ='Food Data'!Q20 -> 0.72 | Z25: ='Food Data'!Q21 -> 4.8 | AA25: ='Food Data'!Q22 -> 3.09 | AB25: ='Food Data'!Q23 -> 4.78 | AC25: ='Food Data'!Q24 -> 23.6 | AD25: ='Food Data'!Q25 -> 22.84 | AE25: ='Food Data'!Q26 -> 12.54 | AF25: ='Food Data'!Q27 -> 7.68 | AG25: ='Food Data'!Q28 -> 17.49 | AH25: ='Food Data'!Q29 -> 2.97 | AI25: ='Food Data'!Q30 -> 3.29 | AJ25: ='Food Data'!Q31 -> 3.89 | AK25: ='Food Data'!Q32 -> 99.98 | AL25: ='Food Data'!Q33 -> 65.36 | AM25: ='Food Data'!Q34 -> 53.83 | AN25: ='Food Data'!Q35 -> 22.31 | AO25: ='Food Data'!Q36 -> 67.7 | AP25: ='Food Data'!Q37 -> 6.64 | AQ25: ='Food Data'!Q38 -> 9.58 | AR25: ='Food Data'!Q39 -> 13.81 | AS25: ='Food Data'!Q40 -> 0 | AT25: ='Food Data'!Q41 -> 0.06
A26: 4 | B26: Fat | C26: g | D26: =$B$7*$B$11/9 -> 57.777778 | E26: =$B$7*$C$11/9 -> 101.11111 | F26: 57.777771 | G26: =IF(F26<D26-0.01,"BELOW MIN",IF(F26>E26+0.01,"ABOVE MAX",IF(OR(ABS(F26-D26)<0.01,ABS(F26-E26)<0.01),"binding","ok"))) -> binding | H26: 70.70036 | I26: =IF(H26<D26-0.01,"BELOW MIN",IF(H26>E26+0.01,"ABOVE MAX",IF(OR(ABS(H26-D26)<0.01,ABS(H26-E26)<0.01),"binding","ok"))) -> ok | K26: ='Food Data'!R6 -> 0.66 | L26: ='Food Data'!R7 -> 1.51 | M26: ='Food Data'!R8 -> 3.33 | N26: ='Food Data'!R9 -> 0.98 | O26: ='Food Data'!R10 -> 1.23 | P26: ='Food Data'!R11 -> 20 | Q26: ='Food Data'!R12 -> 10 | R26: ='Food Data'!R13 -> 14.28 | S26: ='Food Data'!R14 -> 39.69 | T26: ='Food Data'!R15 -> 12.96 | U26: ='Food Data'!R16 -> 8.6 | V26: ='Food Data'!R17 -> 15.06 | W26: ='Food Data'!R18 -> 2.62 | X26: ='Food Data'!R19 -> 15.95 | Y26: ='Food Data'!R20 -> 9.51 | Z26: ='Food Data'!R21 -> 3.25 | AA26: ='Food Data'!R22 -> 33.31 | AB26: ='Food Data'!R23 -> 30.71 | AC26: ='Food Data'!R24 -> 11 | AD26: ='Food Data'!R25 -> 0.33 | AE26: ='Food Data'!R26 -> 0.15 | AF26: ='Food Data'!R27 -> 0.3 | AG26: ='Food Data'!R28 -> 0.09 | AH26: ='Food Data'!R29 -> 0.14 | AI26: ='Food Data'!R30 -> 0.3 | AJ26: ='Food Data'!R31 -> 0.2 | AK26: ='Food Data'!R32 -> 0 | AL26: ='Food Data'!R33 -> 24.72 | AM26: ='Food Data'!R34 -> 33.98 | AN26: ='Food Data'!R35 -> 51.36 | AO26: ='Food Data'!R36 -> 6.52 | AP26: ='Food Data'!R37 -> 0.37 | AQ26: ='Food Data'!R38 -> 0.24 | AR26: ='Food Data'!R39 -> 0.17 | AS26: ='Food Data'!R40 -> 0.96 | AT26: ='Food Data'!R41 -> 81.11
A27: 5 | B27: Fiber | C27: g | D27: =$B$12 -> 38 | E27: 1000000 | F27: 37.999999 | G27: =IF(F27<D27-0.01,"BELOW MIN",IF(F27>E27+0.01,"ABOVE MAX",IF(OR(ABS(F27-D27)<0.01,ABS(F27-E27)<0.01),"binding","ok"))) -> binding | H27: 9.158 | I27: =IF(H27<D27-0.01,"BELOW MIN",IF(H27>E27+0.01,"ABOVE MAX",IF(OR(ABS(H27-D27)<0.01,ABS(H27-E27)<0.01),"binding","ok"))) -> BELOW MIN | K27: ='Food Data'!S6 -> 1.3 | L27: ='Food Data'!S7 -> 3.2 | M27: ='Food Data'!S8 -> 2.7 | N27: ='Food Data'!S9 -> 2.7 | O27: ='Food Data'!S10 -> 15.5 | P27: ='Food Data'!S11 -> 0 | Q27: ='Food Data'!S12 -> 0 | R27: ='Food Data'!S13 -> 0 | S27: ='Food Data'!S14 -> 0 | T27: ='Food Data'!S15 -> 0 | U27: ='Food Data'!S16 -> 1.3 | V27: ='Food Data'!S17 -> 0 | W27: ='Food Data'!S18 -> 0 | X27: ='Food Data'!S19 -> 0 | Y27: ='Food Data'!S20 -> 0 | Z27: ='Food Data'!S21 -> 0 | AA27: ='Food Data'!S22 -> 0 | AB27: ='Food Data'!S23 -> 0 | AC27: ='Food Data'!S24 -> 0.7 | AD27: ='Food Data'!S25 -> 2.6 | AE27: ='Food Data'!S26 -> 2.2 | AF27: ='Food Data'!S27 -> 2 | AG27: ='Food Data'!S28 -> 2.1 | AH27: ='Food Data'!S29 -> 1.2 | AI27: ='Food Data'!S30 -> 2.1 | AJ27: ='Food Data'!S31 -> 1.2 | AK27: ='Food Data'!S32 -> 0 | AL27: ='Food Data'!S33 -> 2 | AM27: ='Food Data'!S34 -> 3.1 | AN27: ='Food Data'!S35 -> 5 | AO27: ='Food Data'!S36 -> 10.1 | AP27: ='Food Data'!S37 -> 2.6 | AQ27: ='Food Data'!S38 -> 2.8 | AR27: ='Food Data'!S39 -> 2.4 | AS27: ='Food Data'!S40 -> 0 | AT27: ='Food Data'!S41 -> 0
A28: 6 | B28: Total sugars | C28: g | D28: 0 | E28: =IF($C$18="",1000000,$C$18) -> 1000000 | F28: 66.26155 | G28: =IF(F28<D28-0.01,"BELOW MIN",IF(F28>E28+0.01,"ABOVE MAX",IF(OR(ABS(F28-D28)<0.01,ABS(F28-E28)<0.01),"binding","ok"))) -> ok | H28: 43.5212 | I28: =IF(H28<D28-0.01,"BELOW MIN",IF(H28>E28+0.01,"ABOVE MAX",IF(OR(ABS(H28-D28)<0.01,ABS(H28-E28)<0.01),"binding","ok"))) -> ok | K28: ='Food Data'!T6 -> 0.12 | L28: ='Food Data'!T7 -> 2.67 | M28: ='Food Data'!T8 -> 5.67 | N28: ='Food Data'!T9 -> 0.27 | O28: ='Food Data'!T10 -> 2.11 | P28: ='Food Data'!T11 -> 0 | Q28: ='Food Data'!T12 -> 0 | R28: ='Food Data'!T13 -> 0 | S28: ='Food Data'!T14 -> 1 | T28: ='Food Data'!T15 -> 0 | U28: ='Food Data'!T16 -> 0 | V28: ='Food Data'!T17 -> 0 | W28: ='Food Data'!T18 -> 0 | X28: ='Food Data'!T19 -> 0 | Y28: ='Food Data'!T20 -> 0.37 | Z28: ='Food Data'!T21 -> 5.05 | AA28: ='Food Data'!T22 -> 0.48 | AB28: ='Food Data'!T23 -> 2.26 | AC28: ='Food Data'!T24 -> 21.22 | AD28: ='Food Data'!T25 -> 12.23 | AE28: ='Food Data'!T26 -> 8.5 | AF28: ='Food Data'!T27 -> 4.89 | AG28: ='Food Data'!T28 -> 0.82 | AH28: ='Food Data'!T29 -> 1.97 | AI28: ='Food Data'!T30 -> 1.19 | AJ28: ='Food Data'!T31 -> 2.63 | AK28: ='Food Data'!T32 -> 99.8 | AL28: ='Food Data'!T33 -> 32.9 | AM28: ='Food Data'!T34 -> 0.33 | AN28: ='Food Data'!T35 -> 10.49 | AO28: ='Food Data'!T36 -> 0.99 | AP28: ='Food Data'!T37 -> 1.7 | AQ28: ='Food Data'!T38 -> 4.74 | AR28: ='Food Data'!T39 -> 10.39 | AS28: ='Food Data'!T40 -> 0 | AT28: ='Food Data'!T41 -> 0.06
A29: 7 | B29: Calcium | C29: mg | D29: =$B$13 -> 1000 | E29: 1000000 | F29: 1438.3049 | G29: =IF(F29<D29-0.01,"BELOW MIN",IF(F29>E29+0.01,"ABOVE MAX",IF(OR(ABS(F29-D29)<0.01,ABS(F29-E29)<0.01),"binding","ok"))) -> ok | H29: 798.748 | I29: =IF(H29<D29-0.01,"BELOW MIN",IF(H29>E29+0.01,"ABOVE MAX",IF(OR(ABS(H29-D29)<0.01,ABS(H29-E29)<0.01),"binding","ok"))) -> BELOW MIN | K29: ='Food Data'!U6 -> 28 | L29: ='Food Data'!U7 -> 21 | M29: ='Food Data'!U8 -> 144 | N29: ='Food Data'!U9 -> 15 | O29: ='Food Data'!U10 -> 113 | P29: ='Food Data'!U11 -> 18 | Q29: ='Food Data'!U12 -> 12 | R29: ='Food Data'!U13 -> 25 | S29: ='Food Data'!U14 -> 5 | T29: ='Food Data'!U15 -> 9 | U29: ='Food Data'!U16 -> 24 | V29: ='Food Data'!U17 -> 11 | W29: ='Food Data'!U18 -> 5 | X29: ='Food Data'!U19 -> 9 | Y29: ='Food Data'!U20 -> 56 | Z29: ='Food Data'!U21 -> 113 | AA29: ='Food Data'!U22 -> 710 | AB29: ='Food Data'!U23 -> 1045 | AC29: ='Food Data'!U24 -> 128 | AD29: ='Food Data'!U25 -> 5 | AE29: ='Food Data'!U26 -> 43 | AF29: ='Food Data'!U27 -> 16 | AG29: ='Food Data'!U28 -> 12 | AH29: ='Food Data'!U29 -> 18 | AI29: ='Food Data'!U30 -> 33 | AJ29: ='Food Data'!U31 -> 10 | AK29: ='Food Data'!U32 -> 1 | AL29: ='Food Data'!U33 -> 21 | AM29: ='Food Data'!U34 -> 21 | AN29: ='Food Data'!U35 -> 49 | AO29: ='Food Data'!U36 -> 52 | AP29: ='Food Data'!U37 -> 47 | AQ29: ='Food Data'!U38 -> 33 | AR29: ='Food Data'!U39 -> 6 | AS29: ='Food Data'!U40 -> 17 | AT29: ='Food Data'!U41 -> 24
A30: 8 | B30: Iron | C30: mg | D30: =$B$14 -> 8 | E30: 1000000 | F30: 21.016711 | G30: =IF(F30<D30-0.01,"BELOW MIN",IF(F30>E30+0.01,"ABOVE MAX",IF(OR(ABS(F30-D30)<0.01,ABS(F30-E30)<0.01),"binding","ok"))) -> ok | H30: 13.31194 | I30: =IF(H30<D30-0.01,"BELOW MIN",IF(H30>E30+0.01,"ABOVE MAX",IF(OR(ABS(H30-D30)<0.01,ABS(H30-E30)<0.01),"binding","ok"))) -> ok | K30: ='Food Data'!V6 -> 4.31 | L30: ='Food Data'!V7 -> 3.3 | M30: ='Food Data'!V8 -> 3.61 | N30: ='Food Data'!V9 -> 4.64 | O30: ='Food Data'!V10 -> 5.07 | P30: ='Food Data'!V11 -> 1.94 | Q30: ='Food Data'!V12 -> 2.24 | R30: ='Food Data'!V13 -> 1.46 | S30: ='Food Data'!V14 -> 0.41 | T30: ='Food Data'!V15 -> 0.48 | U30: ='Food Data'!V16 -> 1.02 | V30: ='Food Data'!V17 -> 0.9 | W30: ='Food Data'!V18 -> 0.37 | X30: ='Food Data'!V19 -> 0.69 | Y30: ='Food Data'!V20 -> 1.75 | Z30: ='Food Data'!V21 -> 0.03 | AA30: ='Food Data'!V22 -> 0.14 | AB30: ='Food Data'!V23 -> 0.63 | AC30: ='Food Data'!V24 -> 0.09 | AD30: ='Food Data'!V25 -> 0.26 | AE30: ='Food Data'!V26 -> 0.13 | AF30: ='Food Data'!V27 -> 0.41 | AG30: ='Food Data'!V28 -> 0.81 | AH30: ='Food Data'!V29 -> 0.41 | AI30: ='Food Data'!V30 -> 0.97 | AJ30: ='Food Data'!V31 -> 0.27 | AK30: ='Food Data'!V32 -> 0.05 | AL30: ='Food Data'!V33 -> 5.58 | AM30: ='Food Data'!V34 -> 1.28 | AN30: ='Food Data'!V35 -> 1.74 | AO30: ='Food Data'!V36 -> 4.25 | AP30: ='Food Data'!V37 -> 0.73 | AQ30: ='Food Data'!V38 -> 0.3 | AR30: ='Food Data'!V39 -> 0.12 | AS30: ='Food Data'!V40 -> 1.63 | AT30: ='Food Data'!V41 -> 0.02
A31: 9 | B31: Potassium | C31: mg | D31: =$B$15 -> 3400 | E31: 1000000 | F31: 4770.0478 | G31: =IF(F31<D31-0.01,"BELOW MIN",IF(F31>E31+0.01,"ABOVE MAX",IF(OR(ABS(F31-D31)<0.01,ABS(F31-E31)<0.01),"binding","ok"))) -> ok | H31: 2474.698 | I31: =IF(H31<D31-0.01,"BELOW MIN",IF(H31>E31+0.01,"ABOVE MAX",IF(OR(ABS(H31-D31)<0.01,ABS(H31-E31)<0.01),"binding","ok"))) -> BELOW MIN | K31: ='Food Data'!W6 -> 115 | L31: ='Food Data'!W7 -> 223 | M31: ='Food Data'!W8 -> 126 | N31: ='Food Data'!W9 -> 107 | O31: ='Food Data'!W10 -> 1393 | P31: ='Food Data'!W11 -> 270 | Q31: ='Food Data'!W12 -> 321 | R31: ='Food Data'!W13 -> 309 | S31: ='Food Data'!W14 -> 198 | T31: ='Food Data'!W15 -> 345 | U31: ='Food Data'!W16 -> 287 | V31: ='Food Data'!W17 -> 189 | W31: ='Food Data'!W18 -> 334 | X31: ='Food Data'!W19 -> 203 | Y31: ='Food Data'!W20 -> 138 | Z31: ='Food Data'!W21 -> 132 | AA31: ='Food Data'!W22 -> 76 | AB31: ='Food Data'!W23 -> 132 | AC31: ='Food Data'!W24 -> 199 | AD31: ='Food Data'!W25 -> 358 | AE31: ='Food Data'!W26 -> 166 | AF31: ='Food Data'!W27 -> 153 | AG31: ='Food Data'!W28 -> 425 | AH31: ='Food Data'!W29 -> 141 | AI31: ='Food Data'!W30 -> 247 | AJ31: ='Food Data'!W31 -> 237 | AK31: ='Food Data'!W32 -> 2 | AL31: ='Food Data'!W33 -> 171 | AM31: ='Food Data'!W34 -> 1196 | AN31: ='Food Data'!W35 -> 558 | AO31: ='Food Data'!W36 -> 362 | AP31: ='Food Data'!W37 -> 316 | AQ31: ='Food Data'!W38 -> 320 | AR31: ='Food Data'!W39 -> 107 | AS31: ='Food Data'!W40 -> 179 | AT31: ='Food Data'!W41 -> 24
A32: 10 | B32: Sodium | C32: mg | D32: 0 | E32: =$C$17 -> 2300 | F32: 565.19358 | G32: =IF(F32<D32-0.01,"BELOW MIN",IF(F32>E32+0.01,"ABOVE MAX",IF(OR(ABS(F32-D32)<0.01,ABS(F32-E32)<0.01),"binding","ok"))) -> ok | H32: 1369.708 | I32: =IF(H32<D32-0.01,"BELOW MIN",IF(H32>E32+0.01,"ABOVE MAX",IF(OR(ABS(H32-D32)<0.01,ABS(H32-E32)<0.01),"binding","ok"))) -> ok | K32: ='Food Data'!X6 -> 5 | L32: ='Food Data'!X7 -> 6 | M32: ='Food Data'!X8 -> 490 | N32: ='Food Data'!X9 -> 2 | O32: ='Food Data'!X10 -> 12 | P32: ='Food Data'!X11 -> 66 | Q32: ='Food Data'!X12 -> 66 | R32: ='Food Data'!X13 -> 51 | S32: ='Food Data'!X14 -> 662 | T32: ='Food Data'!X15 -> 82 | U32: ='Food Data'!X16 -> 1143 | V32: ='Food Data'!X17 -> 70 | W32: ='Food Data'!X18 -> 45 | X32: ='Food Data'!X19 -> 84 | Y32: ='Food Data'!X20 -> 142 | Z32: ='Food Data'!X21 -> 43 | AA32: ='Food Data'!X22 -> 653 | AB32: ='Food Data'!X23 -> 1671 | AC32: ='Food Data'!X24 -> 80 | AD32: ='Food Data'!X25 -> 1 | AE32: ='Food Data'!X26 -> 1 | AF32: ='Food Data'!X27 -> 1 | AG32: ='Food Data'!X28 -> 6 | AH32: ='Food Data'!X29 -> 10 | AI32: ='Food Data'!X30 -> 8 | AJ32: ='Food Data'!X31 -> 5 | AK32: ='Food Data'!X32 -> 1 | AL32: ='Food Data'!X33 -> 311 | AM32: ='Food Data'!X34 -> 527 | AN32: ='Food Data'!X35 -> 426 | AO32: ='Food Data'!X36 -> 6 | AP32: ='Food Data'!X37 -> 33 | AQ32: ='Food Data'!X38 -> 69 | AR32: ='Food Data'!X39 -> 1 | AS32: ='Food Data'!X40 -> 247 | AT32: ='Food Data'!X41 -> 643
A33: 11 | B33: Vitamin C | C33: mg | D33: =$B$16 -> 90 | E33: 1000000 | F33: 89.999985 | G33: =IF(F33<D33-0.01,"BELOW MIN",IF(F33>E33+0.01,"ABOVE MAX",IF(OR(ABS(F33-D33)<0.01,ABS(F33-E33)<0.01),"binding","ok"))) -> binding | H33: 30.66 | I33: =IF(H33<D33-0.01,"BELOW MIN",IF(H33>E33+0.01,"ABOVE MAX",IF(OR(ABS(H33-D33)<0.01,ABS(H33-E33)<0.01),"binding","ok"))) -> BELOW MIN | K33: ='Food Data'!Y6 -> 0 | L33: ='Food Data'!Y7 -> 0 | M33: ='Food Data'!Y8 -> 0 | N33: ='Food Data'!Y9 -> 0 | O33: ='Food Data'!Y10 -> 6.3 | P33: ='Food Data'!Y11 -> 0 | Q33: ='Food Data'!Y12 -> 0 | R33: ='Food Data'!Y13 -> 0 | S33: ='Food Data'!Y14 -> 0 | T33: ='Food Data'!Y15 -> 0 | U33: ='Food Data'!Y16 -> 4 | V33: ='Food Data'!Y17 -> 1.6 | W33: ='Food Data'!Y18 -> 0 | X33: ='Food Data'!Y19 -> 0.2 | Y33: ='Food Data'!Y20 -> 0 | Z33: ='Food Data'!Y21 -> 0 | AA33: ='Food Data'!Y22 -> 0 | AB33: ='Food Data'!Y23 -> 0 | AC33: ='Food Data'!Y24 -> 0.6 | AD33: ='Food Data'!Y25 -> 8.7 | AE33: ='Food Data'!Y26 -> 59.1 | AF33: ='Food Data'!Y27 -> 58.8 | AG33: ='Food Data'!Y28 -> 19.7 | AH33: ='Food Data'!Y29 -> 2.8 | AI33: ='Food Data'!Y30 -> 4 | AJ33: ='Food Data'!Y31 -> 13.7 | AK33: ='Food Data'!Y32 -> 0 | AL33: ='Food Data'!Y33 -> 0 | AM33: ='Food Data'!Y34 -> 21.6 | AN33: ='Food Data'!Y35 -> 0 | AO33: ='Food Data'!Y36 -> 0 | AP33: ='Food Data'!Y37 -> 89.2 | AQ33: ='Food Data'!Y38 -> 5.9 | AR33: ='Food Data'!Y39 -> 4.6 | AS33: ='Food Data'!Y40 -> 0 | AT33: ='Food Data'!Y41 -> 0
B34: c — cost, $ per 100 g edible | C34: cᵀ (row vector) | K34: =IF('Food Data'!J6="",0,'Food Data'!J6) -> 0.24647266 | L34: =IF('Food Data'!J7="",0,'Food Data'!J7) -> 0.30313051 | M34: =IF('Food Data'!J8="",0,'Food Data'!J8) -> 0.40343915 | N34: =IF('Food Data'!J9="",0,'Food Data'!J9) -> 0.12014991 | O34: =IF('Food Data'!J10="",0,'Food Data'!J10) -> 0.36794533 | P34: =IF('Food Data'!J11="",0,'Food Data'!J11) -> 1.4973545 | Q34: =IF('Food Data'!J12="",0,'Food Data'!J12) -> 1.8652998 | R34: =IF('Food Data'!J13="",0,'Food Data'!J13) -> 3.2059674 | S34: =IF('Food Data'!J14="",0,'Food Data'!J14) -> 1.489418 | T34: =IF('Food Data'!J15="",0,'Food Data'!J15) -> 1.0030864 | U34: =IF('Food Data'!J16="",0,'Food Data'!J16) -> 1.2014991 | V34: =IF('Food Data'!J17="",0,'Food Data'!J17) -> 0.66915655 | W34: =IF('Food Data'!J18="",0,'Food Data'!J18) -> 0.9265873 | X34: =IF('Food Data'!J19="",0,'Food Data'!J19) -> 0.52517455 | Y34: =IF('Food Data'!J20="",0,'Food Data'!J20) -> 0.37866667 | Z34: =IF('Food Data'!J21="",0,'Food Data'!J21) -> 0.10517418 | AA34: =IF('Food Data'!J22="",0,'Food Data'!J22) -> 1.3520723 | AB34: =IF('Food Data'!J23="",0,'Food Data'!J23) -> 1.0443122 | AC34: =IF('Food Data'!J24="",0,'Food Data'!J24) -> 0.56164773 | AD34: =IF('Food Data'!J25="",0,'Food Data'!J25) -> 0.22597002 | AE34: =IF('Food Data'!J26="",0,'Food Data'!J26) -> 0.55860307 | AF34: =IF('Food Data'!J27="",0,'Food Data'!J27) -> 0.88808836 | AG34: =IF('Food Data'!J28="",0,'Food Data'!J28) -> 0.29071135 | AH34: =IF('Food Data'!J29="",0,'Food Data'!J29) -> 0.37965284 | AI34: =IF('Food Data'!J30="",0,'Food Data'!J30) -> 0.77676461 | AJ34: =IF('Food Data'!J31="",0,'Food Data'!J31) -> 0.4825862 | AK34: =IF('Food Data'!J32="",0,'Food Data'!J32) -> 0.22464727 | AL34: =IF('Food Data'!J33="",0,'Food Data'!J33) -> 1.1358025 | AM34: =IF('Food Data'!J34="",0,'Food Data'!J34) -> 1.4700176 | AN34: =IF('Food Data'!J35="",0,'Food Data'!J35) -> 0 | AO34: =IF('Food Data'!J36="",0,'Food Data'!J36) -> 0 | AP34: =IF('Food Data'!J37="",0,'Food Data'!J37) -> 0 | AQ34: =IF('Food Data'!J38="",0,'Food Data'!J38) -> 0 | AR34: =IF('Food Data'!J39="",0,'Food Data'!J39) -> 0 | AS34: =IF('Food Data'!J40="",0,'Food Data'!J40) -> 0 | AT34: =IF('Food Data'!J41="",0,'Food Data'!J41) -> 0
B35: u — cap, 100 g units / day | C35: u = 0 when no price | K35: =IF('Food Data'!E6="",0,'Food Data'!K6*'Food Data'!N6/100) -> 1.84 | L35: =IF('Food Data'!E7="",0,'Food Data'!K7*'Food Data'!N7/100) -> 1.71 | M35: =IF('Food Data'!E8="",0,'Food Data'!K8*'Food Data'!N8/100) -> 1.74 | N35: =IF('Food Data'!E9="",0,'Food Data'!K9*'Food Data'!N9/100) -> 0.93 | O35: =IF('Food Data'!E10="",0,'Food Data'!K10*'Food Data'!N10/100) -> 1.92 | P35: =IF('Food Data'!E11="",0,'Food Data'!K11*'Food Data'!N11/100) -> 2.26 | Q35: =IF('Food Data'!E12="",0,'Food Data'!K12*'Food Data'!N12/100) -> 2.26 | R35: =IF('Food Data'!E13="",0,'Food Data'!K13*'Food Data'!N13/100) -> 2.26 | S35: =IF('Food Data'!E14="",0,'Food Data'!K14*'Food Data'!N14/100) -> 0.84 | T35: =IF('Food Data'!E15="",0,'Food Data'!K15*'Food Data'!N15/100) -> 2.26 | U35: =IF('Food Data'!E16="",0,'Food Data'!K16*'Food Data'!N16/100) -> 1.12 | V35: =IF('Food Data'!E17="",0,'Food Data'!K17*'Food Data'!N17/100) -> 2.26 | W35: =IF('Food Data'!E18="",0,'Food Data'!K18*'Food Data'!N18/100) -> 3.39 | X35: =IF('Food Data'!E19="",0,'Food Data'!K19*'Food Data'!N19/100) -> 2.26 | Y35: =IF('Food Data'!E20="",0,'Food Data'!K20*'Food Data'!N20/100) -> 2 | Z35: =IF('Food Data'!E21="",0,'Food Data'!K21*'Food Data'!N21/100) -> 9.76 | AA35: =IF('Food Data'!E22="",0,'Food Data'!K22*'Food Data'!N22/100) -> 0.84 | AB35: =IF('Food Data'!E23="",0,'Food Data'!K23*'Food Data'!N23/100) -> 0.84 | AC35: =IF('Food Data'!E24="",0,'Food Data'!K24*'Food Data'!N24/100) -> 1.32 | AD35: =IF('Food Data'!E25="",0,'Food Data'!K25*'Food Data'!N25/100) -> 3.54 | AE35: =IF('Food Data'!E26="",0,'Food Data'!K26*'Food Data'!N26/100) -> 4.2 | AF35: =IF('Food Data'!E27="",0,'Food Data'!K27*'Food Data'!N27/100) -> 3.04 | AG35: =IF('Food Data'!E28="",0,'Food Data'!K28*'Food Data'!N28/100) -> 4.5 | AH35: =IF('Food Data'!E29="",0,'Food Data'!K29*'Food Data'!N29/100) -> 2.88 | AI35: =IF('Food Data'!E30="",0,'Food Data'!K30*'Food Data'!N30/100) -> 1.88 | AJ35: =IF('Food Data'!E31="",0,'Food Data'!K31*'Food Data'!N31/100) -> 3.6 | AK35: =IF('Food Data'!E32="",0,'Food Data'!K32*'Food Data'!N32/100) -> 0.252 | AL35: =IF('Food Data'!E33="",0,'Food Data'!K33*'Food Data'!N33/100) -> 0.516 | AM35: =IF('Food Data'!E34="",0,'Food Data'!K34*'Food Data'!N34/100) -> 0.56 | AN35: =IF('Food Data'!E35="",0,'Food Data'!K35*'Food Data'!N35/100) -> 0 | AO35: =IF('Food Data'!E36="",0,'Food Data'!K36*'Food Data'!N36/100) -> 0 | AP35: =IF('Food Data'!E37="",0,'Food Data'!K37*'Food Data'!N37/100) -> 0 | AQ35: =IF('Food Data'!E38="",0,'Food Data'!K38*'Food Data'!N38/100) -> 0 | AR35: =IF('Food Data'!E39="",0,'Food Data'!K39*'Food Data'!N39/100) -> 0 | AS35: =IF('Food Data'!E40="",0,'Food Data'!K40*'Food Data'!N40/100) -> 0 | AT35: =IF('Food Data'!E41="",0,'Food Data'!K41*'Food Data'!N41/100) -> 0
A37: 3. DIET VECTORS x (column vectors, 100 g units per day)
A38: x* = optimal solution from the Simplex method for the example targets (pasted values; re-solve after changing targets). Typical day = a hand-built, non-optimized day for comparison (edit freely).
A39: j | B39: Food | C39: x* optimized | D39: u (cap) | E39: grams | F39: servings | G39: cost ($) | H39: at cap? | I39: x typical day | J39: grams | K39: cost ($)
A40: 1 | B40: ='Food Data'!B6 -> White rice (dry) | C40: 0.895308 | D40: =INDEX($K$35:$AT$35,1,A40) -> 1.84 | E40: =C40*100 -> 89.5308 | F40: =E40/'Food Data'!K6 -> 1.9463217 | G40: =C40*INDEX($K$34:$AT$34,1,A40) -> 0.22066895 | H40: =IF(AND(D40>0,ABS(C40-D40)<0.0001),"at cap","") | I40: 0.92 | J40: =I40*100 -> 92 | K40: =I40*INDEX($K$34:$AT$34,1,A40) -> 0.22675485
A41: 2 | B41: ='Food Data'!B7 -> Spaghetti / macaroni (dry) | C41: 0.523443 | D41: =INDEX($K$35:$AT$35,1,A41) -> 1.71 | E41: =C41*100 -> 52.3443 | F41: =E41/'Food Data'!K7 -> 0.91832105 | G41: =C41*INDEX($K$34:$AT$34,1,A41) -> 0.15867154 | H41: =IF(AND(D41>0,ABS(C41-D41)<0.0001),"at cap","") | I41: 0 | J41: =I41*100 -> 0 | K41: =I41*INDEX($K$34:$AT$34,1,A41) -> 0
A42: 3 | B42: ='Food Data'!B8 -> White bread | C42: 0 | D42: =INDEX($K$35:$AT$35,1,A42) -> 1.74 | E42: =C42*100 -> 0 | F42: =E42/'Food Data'!K8 -> 0 | G42: =C42*INDEX($K$34:$AT$34,1,A42) -> 0 | H42: =IF(AND(D42>0,ABS(C42-D42)<0.0001),"at cap","") | I42: 0.58 | J42: =I42*100 -> 58 | K42: =I42*INDEX($K$34:$AT$34,1,A42) -> 0.23399471
A43: 4 | B43: ='Food Data'!B9 -> All-purpose flour | C43: 0.93 | D43: =INDEX($K$35:$AT$35,1,A43) -> 0.93 | E43: =C43*100 -> 93 | F43: =E43/'Food Data'!K9 -> 3 | G43: =C43*INDEX($K$34:$AT$34,1,A43) -> 0.11173942 | H43: =IF(AND(D43>0,ABS(C43-D43)<0.0001),"at cap","") -> at cap | I43: 0 | J43: =I43*100 -> 0 | K43: =I43*INDEX($K$34:$AT$34,1,A43) -> 0
...

Sheet Notes & Sources
A1: How this workbook maps to the project
A2: Food Data = the raw data. Matrix Model = the linear algebra: nutrient matrix A, cost vector c, target vectors b_min / b_max, diet vector x, and the products A·x and cᵀx (MMULT).
A3: Section 4 proves the answer with a square linear system (MINVERSE, MDETERM); sections 5–6 give shadow prices and the optimality certificate.
A4: The website optimizer (diet-optimizer.js) uses exactly this A, c, b and solves it with a two-phase Simplex written as Gauss-Jordan row operations.
A6: Re-solving inside Excel (Solver add-in, Data → Solver)
A7: Set Objective: 'Matrix Model'!G76 To: Min By Changing Variable Cells: 'Matrix Model'!C40:C75
A8: Constraints: F23:F33 >= D23:D33; F23:F33 <= E23:E33; C40:C75 <= D40:D75. Tick 'Make Unconstrained Variables Non-Negative'. Solving Method: Simplex LP.
A9: Google Sheets: install the free "Solver" add-on, or paste x from the website. Sections 4–6 only apply to the example targets until you re-derive the tight constraints.
A11: Assumptions to state in the presentation
A12: 1. Prices are national averages (BLS U.S. city average), not Tampa store prices. Regional prices differ; a store-specific price list can replace column E of Food Data.
A13: 2. Nutrients are per 100 g of the food as bought and edible (raw meat, dry rice/pasta/beans). Cooking mostly changes water weight; small cooking losses (e.g., vitamin C, fat dripping from meat) are ignored.
A14: 3. Prices are converted to $ per 100 g EDIBLE portion with USDA refuse percentages (bone in chicken, peel on bananas/oranges, shells on eggs). Without this, bone-in chicken looks ~30% cheaper than it is.
... A32: Blue text = input data you can edit. Black = formula. Green = link to another sheet. Yellow fill = price still needed. Grey fill = matrix-product results.
